<?xml version="1.1" encoding="utf-8"?>
<!-- =================================================================================== -->
<!-- Copyright 2024 PNDbotics, https://www.pndbotics.com/ -->
<!-- =================================================================================== -->
<!-- This file contains the description of the adam lite robot. -->
<robot name="adam_sp">
	<!-- <link name="world"/> -->
	<link name="pelvis">
		<inertial>
			<origin xyz="-0.00034724 0.00000000 -0.00735759" rpy="0 0 0" />
			<mass value="10.35646604" />
			<inertia ixx="0.06211831" ixy="-0.00000103" ixz="-0.00007613" iyy="0.03451514" iyz="0.00000020" izz="0.06877943" />
		</inertial>
		<visual>
			<origin xyz="0 0 0" rpy="0 0 0" />
			<geometry>
				<mesh filename="meshes/pelvis.dae" />
			</geometry>
			<material name="">
				<color rgba="1 1 1 1" />
			</material>
		</visual>
		<collision>
			<origin xyz="0.0 0.0 0" rpy="1.57 0 0" />
			<geometry>
				<cylinder length="0.1" radius="0.1" />
			</geometry>
		</collision>
	</link>
	<joint name="imu_joint" type="fixed">
		<parent link="pelvis" />
		<child link="imu_link" />
		<origin rpy="0 0 0" xyz="0 0 0" />
	</joint>
	<link name="imu_link">
		<inertial>
			<mass value="0.001" />
			<origin rpy="0 0 0" xyz="0 0 0" />
			<inertia ixx="0.0001" ixy="0" ixz="0" iyy="0.0001" iyz="0" izz="0.0001" />
		</inertial>
		<visual>
			<origin rpy="0 0 0" xyz="0 0 0" />
			<geometry>
				<mesh filename="meshes/vn100-0001.dae" />
			</geometry>
		</visual>
	</link>
<!-- 	
	<joint name="floating_joint" type="floating">
	<parent link="world"/>
	<child link="pelvis"/>
	<origin xyz="0 0 0" rpy="0 0 0"/>
	<axis xyz="0 0 0 1 0 0" />
	<axis xyz="0 0 0 0 1 0" />
	<axis xyz="0 0 0 0 0 1" />
	<axis xyz="1 0 0" />
	<axis xyz="0 1 0" />
	<axis xyz="0 0 1" />
	</joint>
	 -->
	<link name="hipPitchLeft">
		<inertial>
			<origin xyz="-0.05660220 0.05761439 -0.00077159" rpy="0 0 0" />
			<mass value="2.23379987" />
			<inertia ixx="0.00362189" ixy="-0.00107609" ixz="0.00002179" iyy="0.00439139" iyz="0.00004441" izz="0.00515496" />
		</inertial>
		<visual>
			<origin xyz="0 0 0" rpy="0 0 0" />
			<geometry>
				<mesh filename="meshes/hipPitchLeft.dae" />
			</geometry>
			<material name="">
				<color rgba="1 1 1 1" />
			</material>
		</visual>
	</link>
	<joint name="hipPitch_Left" type="revolute">
		<origin xyz="0 0.096192 -0.033241" rpy="-0.61087 0 0" />
		<parent link="pelvis" />
		<child link="hipPitchLeft" />
		<axis xyz="0 1 0" />
		<limit effort="230.0" lower="-2.164" upper="2.164" velocity="15.0" />
	</joint>
	<link name="hipRollLeft">
		<inertial>
			<origin xyz="0.03924162 0.00004107 -0.01032916" rpy="0 0 0" />
			<mass value="1.35107789" />
			<inertia ixx="0.00122242" ixy="-0.00000463" ixz="-0.00007104" iyy="0.00129116" iyz="-0.00000767" izz="0.00138754" />
		</inertial>
		<visual>
			<origin xyz="0 0 0" rpy="0 0 0" />
			<geometry>
				<mesh filename="meshes/hipRollLeft.dae" />
			</geometry>
			<material name="">
				<color rgba="1 1 1 1" />
			</material>
		</visual>
	</link>
	<joint name="hipRoll_Left" type="revolute">
		<origin xyz="-0.0255 0.069 0" rpy="0.61087 0 0" />
		<parent link="hipPitchLeft" />
		<child link="hipRollLeft" />
		<axis xyz="1 0 0" />
		<limit effort="160.0" lower="-0.733" upper="1.605" velocity="8.0" />
	</joint>
	<link name="thighLeft">
		<inertial>
			<origin xyz="0.00244052 -0.00866423 -0.13433631" rpy="0 0 0" />
			<mass value="6.43432838" />
			<inertia ixx="0.05827182" ixy="-0.00024775" ixz="-0.00135721" iyy="0.06333936" iyz="0.00551470" izz="0.01331159" />
		</inertial>
		<visual>
			<origin xyz="0 0 0" rpy="0 0 0" />
			<geometry>
				<mesh filename="meshes/thighLeft.dae" />
			</geometry>
			<material name="">
				<color rgba="1 1 1 1" />
			</material>
		</visual>
		<collision>
			<origin xyz="0.0 -0.01 -0.13" rpy="-0.174533 0 0" />
			<geometry>
				<cylinder length="0.08" radius="0.06" />
			</geometry>
		</collision>
	</link>
	<joint name="hipYaw_Left" type="revolute">
		<origin xyz="0.044 0 -0.0525" rpy="0 0 0" />
		<parent link="hipRollLeft" />
		<child link="thighLeft" />
		<axis xyz="0 0 1" />
		<limit effort="105" lower="-0.785" upper="0.785" velocity="8.0" />
	</joint>
	<link name="shinLeft">
		<inertial>
			<origin xyz="-0.00053135 0.00081959 -0.14538124" rpy="0 0 0" />
			<mass value="2.25363003" />
			<inertia ixx="0.02151350" ixy="-0.00001764" ixz="0.00032260" iyy="0.02158746" iyz="0.00004329" izz="0.00136992" />
		</inertial>
		<visual>
			<origin xyz="0 0 0" rpy="0 0 0" />
			<geometry>
				<mesh filename="meshes/shinLeft.dae" />
			</geometry>
			<material name="">
				<color rgba="1 1 1 1" />
			</material>
		</visual>
		<collision>
			<origin xyz="0.0 0.0 -0.17" rpy="0 0 0" />
			<geometry>
				<cylinder length="0.22" radius="0.04" />
			</geometry>
		</collision>
	</link>
	<joint name="kneePitch_Left" type="revolute">
		<origin xyz="0 -0.0355 -0.369" rpy="0 0 0" />
		<parent link="thighLeft" />
		<child link="shinLeft" />
		<axis xyz="0 1 0" />
		<limit effort="230.0" lower="0.052" upper="2.391" velocity="15.0" />
	</joint>
	<link name="anklePitchLeft">
		<inertial>
			<origin xyz="0.00000000 0.00000000 0.00000000" rpy="0 0 0" />
			<mass value="0.03014230" />
			<inertia ixx="0.00000314" ixy="0.00000000" ixz="0.00000000" iyy="0.00000314" iyz="0.00000000" izz="0.00000204" />
		</inertial>
		<visual>
			<origin xyz="0 0 0" rpy="0 0 0" />
			<geometry>
				<mesh filename="meshes/anklePitchLeft.dae" />
			</geometry>
			<material name="">
				<color rgba="1 1 1 1" />
			</material>
		</visual>
	</link>
	<joint name="anklePitch_Left" type="revolute">
		<origin xyz="0 0 -0.37" rpy="0 0 0" />
		<parent link="shinLeft" />
		<child link="anklePitchLeft" />
		<axis xyz="0 1 0" />
		<limit effort="40.0" lower="-1.0" upper="0.35" velocity="20.0" />
	</joint>
	<link name="toeLeft">
		<inertial>
			<origin xyz="0.03749965 -0.00004016 -0.04196743" rpy="0 0 0" />
			<mass value="0.63479601" />
			<inertia ixx="0.00045636" ixy="0.00001603" ixz="-0.00020108" iyy="0.00226894" iyz="0.00000180" izz="0.00231317" />
		</inertial>
		<visual>
			<origin xyz="0 0 0" rpy="0 0 0" />
			<geometry>
				<mesh filename="meshes/toeLeft.dae" />
			</geometry>
			<material name="">
				<color rgba="0.752941176470588 0.752941176470588 0.752941176470588 1" />
			</material>
		</visual>
		<collision name="toe_left">
			<origin rpy="0 0 0" xyz="0 0 0" />
			<geometry>
				<mesh filename="meshes/toeLeft.dae" />
			</geometry>
		</collision>
	</link>
	<joint name="ankleRoll_Left" type="revolute">
		<origin xyz="0 0 0" rpy="0 0 0" />
		<parent link="anklePitchLeft" />
		<child link="toeLeft" />
		<axis xyz="1 0 0" />
		<limit effort="12.0" lower="-0.3491" upper="0.3491" velocity="20.0" />
	</joint>
	<link name="hipPitchRight">
		<inertial>
			<origin xyz="-0.05661792 -0.05759336 -0.00078211" rpy="0 0 0" />
			<mass value="2.23477271" />
			<inertia ixx="0.00362315" ixy="0.00107435" ixz="0.00002228" iyy="0.00439419" iyz="-0.00004505" izz="0.00515804" />
		</inertial>
		<visual>
			<origin xyz="0 0 0" rpy="0 0 0" />
			<geometry>
				<mesh filename="meshes/hipPitchRight.dae" />
			</geometry>
			<material name="">
				<color rgba="1 1 1 1" />
			</material>
		</visual>
	</link>
	<joint name="hipPitch_Right" type="revolute">
		<origin xyz="0 -0.096192 -0.033241" rpy="0.61087 0 0" />
		<parent link="pelvis" />
		<child link="hipPitchRight" />
		<axis xyz="0 1 0" />
		<limit effort="230.0" lower="-2.164" upper="2.164" velocity="15.0" />
	</joint>
	<link name="hipRollRight">
		<inertial>
			<origin xyz="0.03925975 -0.00005814 -0.01032408" rpy="0 0 0" />
			<mass value="1.35169943" />
			<inertia ixx="0.00122275" ixy="0.00000501" ixz="-0.00007267" iyy="0.00129208" iyz="0.00000835" izz="0.00138861" />
		</inertial>
		<visual>
			<origin xyz="0 0 0" rpy="0 0 0" />
			<geometry>
				<mesh filename="meshes/hipRollRight.dae" />
			</geometry>
			<material name="">
				<color rgba="1 1 1 1" />
			</material>
		</visual>
	</link>
	<joint name="hipRoll_Right" type="revolute">
		<origin xyz="-0.0255 -0.069 0" rpy="-0.61087 0 0" />
		<parent link="hipPitchRight" />
		<child link="hipRollRight" />
		<axis xyz="1 0 0" />
		<limit effort="160.0" lower="-1.605" upper="0.733" velocity="8.0" />
	</joint>
	<link name="thighRight">
		<inertial>
			<origin xyz="0.00245598 0.00865064 -0.13433188" rpy="0 0 0" />
			<mass value="6.43084152" />
			<inertia ixx="0.05823192" ixy="0.00024481" ixz="-0.00134046" iyy="0.06331326" iyz="-0.00551858" izz="0.01331917" />
		</inertial>
		<visual>
			<origin xyz="0 0 0" rpy="0 0 0" />
			<geometry>
				<mesh filename="meshes/thighRight.dae" />
			</geometry>
			<material name="">
				<color rgba="1 1 1 1" />
			</material>
		</visual>
		<collision>
			<origin xyz="0.0 0.01 -0.13" rpy="0 0 0" />
			<geometry>
				<cylinder length="0.08" radius="0.06" />
			</geometry>
		</collision>
	</link>
	<joint name="hipYaw_Right" type="revolute">
		<origin xyz="0.044 0 -0.0525" rpy="0 0 0" />
		<parent link="hipRollRight" />
		<child link="thighRight" />
		<axis xyz="0 0 1" />
		<limit effort="105" lower="-0.785" upper="0.785" velocity="8.0" />
	</joint>
	<link name="shinRight">
		<inertial>
			<origin xyz="-0.00052844 -0.00082152 -0.14533361" rpy="0 0 0" />
			<mass value="2.25459286" />
			<inertia ixx="0.02149493" ixy="0.00001649" ixz="0.00032142" iyy="0.02156785" iyz="-0.00004501" izz="0.00137005" />
		</inertial>
		<visual>
			<origin xyz="0 0 0" rpy="0 0 0" />
			<geometry>
				<mesh filename="meshes/shinRight.dae" />
			</geometry>
			<material name="">
				<color rgba="1 1 1 1" />
			</material>
		</visual>
		<collision>
			<origin xyz="0.0 0.0 -0.17" rpy="0 0 0" />
			<geometry>
				<cylinder length="0.22" radius="0.04" />
			</geometry>
		</collision>
	</link>
	<joint name="kneePitch_Right" type="revolute">
		<origin xyz="0 0.0355 -0.369" rpy="0 0 0" />
		<parent link="thighRight" />
		<child link="shinRight" />
		<axis xyz="0 1 0" />
		<limit effort="230.0" lower="0.052" upper="2.391" velocity="15.0" />
	</joint>
	<link name="anklePitchRight">
		<inertial>
			<origin xyz="0.00000000 0.00000000 0.00000000" rpy="0 0 0" />
			<mass value="0.03014230" />
			<inertia ixx="0.00000314" ixy="0.00000000" ixz="0.00000000" iyy="0.00000314" iyz="0.00000000" izz="0.00000204" />
		</inertial>
		<visual>
			<origin xyz="0 0 0" rpy="0 0 0" />
			<geometry>
				<mesh filename="meshes/anklePitchRight.dae" />
			</geometry>
			<material name="">
				<color rgba="0.752941176470588 0.752941176470588 0.752941176470588 1" />
			</material>
		</visual>
	</link>
	<joint name="anklePitch_Right" type="revolute">
		<origin xyz="0 0 -0.37" rpy="0 0 0" />
		<parent link="shinRight" />
		<child link="anklePitchRight" />
		<axis xyz="0 1 0" />
		<limit effort="40.0" lower="-1.0" upper="0.35" velocity="20.0" />
	</joint>
	<link name="toeRight">
		<inertial>
			<origin xyz="0.03750226 0.00004002 -0.04196714" rpy="0 0 0" />
			<mass value="0.63480789" />
			<inertia ixx="0.00045639" ixy="-0.00001603" ixz="-0.00020109" iyy="0.00226894" iyz="-0.00000181" izz="0.00231317" />
		</inertial>
		<visual>
			<origin xyz="0 0 0" rpy="0 0 0" />
			<geometry>
				<mesh filename="meshes/toeRight.dae" />
			</geometry>
			<material name="">
				<color rgba="0.752941176470588 0.752941176470588 0.752941176470588 1" />
			</material>
		</visual>
		<collision name="toe_right">
			<origin rpy="0 0 0" xyz="0 0 0" />
			<geometry>
				<mesh filename="meshes/toeRight.dae" />
			</geometry>
		</collision>
	</link>
	<joint name="ankleRoll_Right" type="revolute">
		<origin xyz="0 0 0" rpy="0 0 0" />
		<parent link="anklePitchRight" />
		<child link="toeRight" />
		<axis xyz="1 0 0" />
		<limit effort="12.0" lower="-0.3491" upper="0.3491" velocity="20.0" />
	</joint>
	<link name="waistRoll">
		<inertial>
			<origin xyz="0.00093826 0.00093832 0.03999995" rpy="0 0 0" />
			<mass value="2.36268465" />
			<inertia ixx="0.00543041" ixy="-0.00000171" ixz="-0.00006791" iyy="0.00543044" iyz="0.00006793" izz="0.00184993" />
		</inertial>
		<visual>
			<origin xyz="0 0 0" rpy="0 0 0" />
			<geometry>
				<mesh filename="meshes/waistRoll.dae" />
			</geometry>
			<material name="">
				<color rgba="1 1 1 1" />
			</material>
		</visual>
	</link>
	<joint name="waistRoll" type="revolute">
		<origin xyz="0 0 0.044" rpy="0 0 0" />
		<parent link="pelvis" />
		<child link="waistRoll" />
		<axis xyz="1 0 0" />
		<limit effort="110" lower="-0.226" upper="0.226" velocity="8.0" />
	</joint>
	<link name="waistPitch">
		<inertial>
			<origin xyz="-0.00008401 0.00189362 0.02548321" rpy="0 0 0" />
			<mass value="0.56353776" />
			<inertia ixx="0.00151470" ixy="0.00001037" ixz="0.00000444" iyy="0.00067279" iyz="-0.00001192" izz="0.00155907" />
		</inertial>
		<visual>
			<origin xyz="0 0 0" rpy="0 0 0" />
			<geometry>
				<mesh filename="meshes/waistPitch.dae" />
			</geometry>
			<material name="">
				<color rgba="1 1 1 1" />
			</material>
		</visual>
	</link>
	<joint name="waistPitch" type="revolute">
		<origin xyz="0 0 0.08" rpy="0 0 0" />
		<parent link="waistRoll" />
		<child link="waistPitch" />
		<axis xyz="0 1 0" />
		<limit effort="110" lower="-0.785" upper="1.308" velocity="8.0" />
	</joint>
	<link name="torso">
		<inertial>
			<origin xyz="0.00014300 0.00050556 0.18336920" rpy="0 0 0" />
			<mass value="12.89652496" />
			<inertia ixx="0.19855642" ixy="-0.00036714" ixz="0.00331900" iyy="0.16612827" iyz="-0.00021516" izz="0.06625123" />
		</inertial>
		<visual>
			<origin xyz="0 0 0" rpy="0 0 0" />
			<geometry>
				<mesh filename="meshes/torso.dae" />
			</geometry>
			<material name="">
				<color rgba="1 1 1 1" />
			</material>
		</visual>
		<collision>
			<origin xyz="0 0 0.15" rpy="0 0 0" />
			<geometry>
				<sphere radius="0.13" />
			</geometry>
		</collision>
	</link>
	<joint name="waistYaw" type="revolute">
		<origin xyz="0 0.0005 0.053" rpy="0 0 0" />
		<parent link="waistPitch" />
		<child link="torso" />
		<axis xyz="0 0 1" />
		<limit effort="110" lower="-0.78" upper="0.78" velocity="8.0" />
	</joint>
	<link name="shoulderPitchLeft">
		<inertial>
			<origin xyz="-0.00150404 0.02688841 0.00010848" rpy="0 0 0" />
			<mass value="0.20310000" />
			<inertia ixx="0.00017020" ixy="-0.00000461" ixz="-0.00000064" iyy="0.00028895" iyz="0.00000042" izz="0.00034385" />
		</inertial>
		<visual>
			<origin xyz="0 0 0" rpy="0 0 0" />
			<geometry>
				<mesh filename="meshes/shoulderPitchLeft.dae" />
			</geometry>
			<material name="">
				<color rgba="1 1 1 1" />
			</material>
		</visual>
	</link>
	<joint name="shoulderPitch_Left" type="revolute">
		<origin xyz="0 0.16011 0.25742" rpy="0.34907 0 0" />
		<parent link="torso" />
		<child link="shoulderPitchLeft" />
		<axis xyz="0 1 0" />
		<limit effort="65.0" lower="-3.560" upper="1.989" velocity="8.0" />
	</joint>
	<link name="shoulderRollLeft">
		<inertial>
			<origin xyz="-0.02860447 0.01104245 -0.01405309" rpy="0 0 0" />
			<mass value="0.72480000" />
			<inertia ixx="0.00090812" ixy="-0.00002621" ixz="0.00003997" iyy="0.00071197" iyz="-0.00025129" izz="0.00060954" />
		</inertial>
		<visual>
			<origin xyz="0 0 0" rpy="0 0 0" />
			<geometry>
				<mesh filename="meshes/shoulderRollLeft.dae" />
			</geometry>
			<material name="">
				<color rgba="1 1 1 1" />
			</material>
		</visual>
		<collision>
			<origin xyz="-0.035 0 0" rpy="0 1.5708 0" />
			<geometry>
				<cylinder length="0.02" radius="0.035" />
			</geometry>
		</collision>
	</link>
	<joint name="shoulderRoll_Left" type="revolute">
		<origin xyz="0.0335 0.0435 0" rpy="-0.34907 0 0" />
		<parent link="shoulderPitchLeft" />
		<child link="shoulderRollLeft" />
		<axis xyz="1 0 0" />
		<limit effort="65.0" lower="-0.575" upper="2.74" velocity="8.0" />
	</joint>
	<link name="shoulderYawLeft">
		<inertial>
			<origin xyz="-0.00069813 0.00102049 -0.06842313" rpy="0 0 0" />
			<mass value="0.69630000" />
			<inertia ixx="0.00317887" ixy="0.00000059" ixz="0.00005528" iyy="0.00310433" iyz="-0.00009472" izz="0.00039452" />
		</inertial>
		<visual>
			<origin xyz="0 0 0" rpy="0 0 0" />
			<geometry>
				<mesh filename="meshes/shoulderYawLeft.dae" />
			</geometry>
			<material name="">
				<color rgba="1 1 1 1" />
			</material>
		</visual>
		<collision>
			<origin xyz="0 0 -0.06" rpy="0 0 0" />
			<geometry>
				<cylinder length="0.067" radius="0.0415" />
			</geometry>
		</collision>
	</link>
	<joint name="shoulderYaw_Left" type="revolute">
		<origin xyz="-0.0335 0.034 -0.0585" rpy="0 0 0" />
		<parent link="shoulderRollLeft" />
		<child link="shoulderYawLeft" />
		<axis xyz="0 0 1" />
		<limit effort="65.0" lower="-1.6" upper="1.6" velocity="8.0" />
	</joint>
	<link name="elbowLeft">
		<inertial>
			<origin xyz="-0.01212328 0.02629569 -0.02658404" rpy="0 0 0" />
			<mass value="0.85400000" />
			<inertia ixx="0.00072987" ixy="-0.00001380" ixz="0.00015644" iyy="0.00080410" iyz="-0.00002763" izz="0.00047565" />
		</inertial>
		<visual>
			<origin xyz="0 0 0" rpy="0 0 0" />
			<geometry>
				<mesh filename="meshes/elbowLeft.dae" />
			</geometry>
			<material name="">
				<color rgba="1 1 1 1" />
			</material>
		</visual>
	</link>
	<joint name="elbow_Left" type="revolute">
		<origin xyz="0 -0.0285 -0.20415" rpy="0 0 0" />
		<parent link="shoulderYawLeft" />
		<child link="elbowLeft" />
		<axis xyz="0 1 0" />
		<limit effort="30.0" lower="-2.0" upper="0.0" velocity="8.0" />
	</joint>
	<link name="wristYawLeft">
		<inertial>
			<origin xyz="-0.00202981 0.00013146 -0.09216894" rpy="0 0 0" />
			<mass value="0.95587869" />
			<inertia ixx="0.00256138" ixy="-0.00000268" ixz="0.00003060" iyy="0.00250125" iyz="-0.00002660" izz="0.00055105" />
		</inertial>
		<visual>
			<origin xyz="0 0 0" rpy="0 0 0" />
			<geometry>
				<mesh filename="meshes/wristYawLeft.dae" />
			</geometry>
			<material name="">
				<color rgba="1 1 1 1" />
			</material>
		</visual>
		<collision>
			<origin xyz="0 0 -0.09" rpy="0 0 0" />
			<geometry>
				<cylinder length="0.1" radius="0.038"/>
			</geometry>
		</collision>
	</link>
	<joint name="wristYaw_Left" type="revolute">
		<origin xyz="-0.025 0.0285 -0.0729" rpy="0 0 0" />
		<parent link="elbowLeft" />
		<child link="wristYawLeft" />
		<axis xyz="0 0 1" />
		<limit effort="6.4" lower="-2.617" upper="2.617" velocity="4.9218" />
	</joint>
	<link name="wristPitchLeft">
		<inertial>
			<origin xyz="-0.00017580 0.00166098 -0.00002773" rpy="0 0 0" />
			<mass value="0.11963454" />
			<inertia ixx="0.00003359" ixy="0.00000002" ixz="0.00000000" iyy="0.00002690" iyz="-0.00000005" izz="0.00003977" />
		</inertial>
		<visual>
			<origin xyz="0 0 0" rpy="0 0 0" />
			<geometry>
				<mesh filename="meshes/wristPitchLeft.dae" />
			</geometry>
			<material name="">
				<color rgba="1 1 1 1" />
			</material>
		</visual>
	</link>
	<joint name="wristPitch_Left" type="revolute">
		<origin xyz="0 0 -0.2017" rpy="0 0 0" />
		<parent link="wristYawLeft" />
		<child link="wristPitchLeft" />
		<axis xyz="0 1 0" />
		<limit effort="6.4" lower="-0.907" upper="0.907" velocity="4.9218" />
	</joint>
	<link name="wristRollLeft">
		<inertial>
			<origin xyz="-0.00027229 0.008645 -0.06627" rpy="0 0 0" />
			<mass value="0.3575" />
			<inertia ixx="0.00032014" ixy="1.166E-05" ixz="-4.03E-06" iyy="0.00042954" iyz="-2.167E-05" izz="0.00018487" />
		</inertial>
		<visual>
			<origin xyz="0 0 0" rpy="0 0 0" />
			<geometry>
				<mesh filename="meshes/wristRollLeft.dae" />
			</geometry>
			<material name="">
				<color rgba="0.75294 0.75294 0.75294 1" />
			</material>
		</visual>
		<collision>
			<origin xyz="0 0 0" rpy="0 0 0" />
			<geometry>
				<mesh filename="meshes/wristRollLeft.dae" />
			</geometry>
		</collision>
	</link>
	<joint name="wristRoll_Left" type="revolute">
		<origin xyz="0 0 0" rpy="0 0 0" />
		<parent link="wristPitchLeft" />
		<child link="wristRollLeft" />
		<axis xyz="1 0 0" />
		<limit effort="6.4" lower="-0.907" upper="0.907" velocity="4.9218" />
	</joint>
	<link name="L_thumb_proximal_base">
		<inertial>
			<origin xyz="0.0043163 0.00026726 -0.0014189" rpy="0 0 0" />
			<mass value="0.0089319" />
			<inertia ixx="3.1E-07" ixy="-8E-08" ixz="-6E-08" iyy="5.5E-07" iyz="1E-08" izz="4.6E-07" />
		</inertial>
		<visual>
			<origin xyz="0 0 0" rpy="0 0 0" />
			<geometry>
				<mesh filename="meshes/L_thumb_proximal_base.dae" />
			</geometry>
			<material name="">
				<color rgba="0.75294 0.75294 0.75294 1" />
			</material>
		</visual>
		<collision>
			<origin xyz="0 0 0" rpy="0 0 0" />
			<geometry>
				<mesh filename="meshes/L_thumb_proximal_base.dae" />
			</geometry>
		</collision>
	</link>
	<joint name="Lthumb_proximal_base" type="fixed">
		<origin xyz="0.024499999999999 -0.0100000000000017 -0.047" rpy="0 0 0" />
		<parent link="wristRollLeft" />
		<child link="L_thumb_proximal_base" />
		<axis xyz="0 0 1" />
	</joint>
	<link name="L_thumb_proximal">
		<inertial>
			<origin xyz="0.023697 0 -0.014672" rpy="0 0 0" />
			<mass value="0.061584" />
			<inertia ixx="1.171E-05" ixy="0" ixz="-5.75E-06" iyy="2.013E-05" iyz="0" izz="1.139E-05" />
		</inertial>
		<visual>
			<origin xyz="0 0 0" rpy="0 0 0" />
			<geometry>
				<mesh filename="meshes/L_thumb_proximal.dae" />
			</geometry>
			<material name="">
				<color rgba="0.75294 0.75294 0.75294 1" />
			</material>
		</visual>
		<collision>
			<origin xyz="0 0 0" rpy="0 0 0" />
			<geometry>
				<mesh filename="meshes/L_thumb_proximal.dae" />
			</geometry>
		</collision>
	</link>
	<joint name="Lthumb_proximal" type="fixed">
		<origin xyz="0.0119540024564371 -0.0010496786515381 0" rpy="0 0 -0.0875851579771298" />
		<parent link="L_thumb_proximal_base" />
		<child link="L_thumb_proximal" />
		<axis xyz="0 1 0" />
	</joint>
	<link name="L_thumb_intermediate">
		<inertial>
			<origin xyz="0.0097313 0 -0.0026647" rpy="0 0 0" />
			<mass value="0.015383" />
			<inertia ixx="1.42E-06" ixy="0" ixz="-3.9E-07" iyy="1.72E-06" iyz="0" izz="1E-06" />
		</inertial>
		<visual>
			<origin xyz="0 0 0" rpy="0 0 0" />
			<geometry>
				<mesh filename="meshes/L_thumb_intermediate.dae" />
			</geometry>
			<material name="">
				<color rgba="0.75294 0.75294 0.75294 1" />
			</material>
		</visual>
		<collision>
			<origin xyz="0 0 0" rpy="0 0 0" />
			<geometry>
				<mesh filename="meshes/L_thumb_intermediate.dae" />
			</geometry>
		</collision>
	</link>
	<joint name="Lthumb_intermediate" type="fixed">
		<origin xyz="0.04428856411629 0 -0.03766328568403" rpy="0 0 0" />
		<parent link="L_thumb_proximal" />
		<child link="L_thumb_intermediate" />
		<axis xyz="0 1 0" />
	</joint>
	<link name="L_thumb_distal">
		<inertial>
			<origin xyz="0.0071422 -1.54E-06 -0.006894" rpy="0 0 0" />
			<mass value="0.010437" />
			<inertia ixx="7.6E-07" ixy="0" ixz="-2E-07" iyy="8.6E-07" iyz="0" izz="5.2E-07" />
		</inertial>
		<visual>
			<origin xyz="0 0 0" rpy="0 0 0" />
			<geometry>
				<mesh filename="meshes/L_thumb_distal.dae" />
			</geometry>
			<material name="">
				<color rgba="0.75294 0.75294 0.75294 1" />
			</material>
		</visual>
		<collision>
			<origin xyz="0 0 0" rpy="0 0 0" />
			<geometry>
				<mesh filename="meshes/L_thumb_distal.dae" />
			</geometry>
		</collision>
	</link>
	<joint name="Lthumb_distal" type="fixed">
		<origin xyz="0.01646793433544 0 -0.0154614727217" rpy="0 0 0" />
		<parent link="L_thumb_intermediate" />
		<child link="L_thumb_distal" />
		<axis xyz="0 1 0" />
	</joint>
	<link name="L_index_proximal">
		<inertial>
			<origin xyz="0 0.0019982 -0.013117" rpy="0 0 0" />
			<mass value="0.014541" />
			<inertia ixx="1.95E-06" ixy="0" ixz="0" iyy="1.95E-06" iyz="2E-08" izz="5.4E-07" />
		</inertial>
		<visual>
			<origin xyz="0 0 0" rpy="0 0 0" />
			<geometry>
				<mesh filename="meshes/L_index_proximal.dae" />
			</geometry>
			<material name="">
				<color rgba="0.75294 0.75294 0.75294 1" />
			</material>
		</visual>
		<collision>
			<origin xyz="0 0 0" rpy="0 0 0" />
			<geometry>
				<mesh filename="meshes/L_index_proximal.dae" />
			</geometry>
		</collision>
	</link>
	<joint name="Lindex_proximal" type="fixed">
		<origin xyz="0.0269420472123676 0.00950000000000051 -0.11497533162558" rpy="0 -0.052359877559825 0" />
		<parent link="wristRollLeft" />
		<child link="L_index_proximal" />
		<axis xyz="-1 0 0" />
	</joint>
	<link name="L_index_distal">
		<inertial>
			<origin xyz="0 0.0016895 -0.015369" rpy="0 0 0" />
			<mass value="0.009059" />
			<inertia ixx="1.73E-06" ixy="0" ixz="0" iyy="1.68E-06" iyz="2.5E-07" izz="2.5E-07" />
		</inertial>
		<visual>
			<origin xyz="0 0 0" rpy="0 0 0" />
			<geometry>
				<mesh filename="meshes/L_index_distal.dae" />
			</geometry>
			<material name="">
				<color rgba="0.75294 0.75294 0.75294 1" />
			</material>
		</visual>
		<collision>
			<origin xyz="0 0 0" rpy="0 0 0" />
			<geometry>
				<mesh filename="meshes/L_index_distal.dae" />
			</geometry>
		</collision>
	</link>
	<joint name="Lindex_distal" type="fixed">
		<origin xyz="0 -0.00111268989727942 -0.0319806491677798" rpy="0 0 0" />
		<parent link="L_index_proximal" />
		<child link="L_index_distal" />
		<axis xyz="-1 0 0" />
	</joint>
	<link name="L_middle_proximal">
		<inertial>
			<origin xyz="0 0.0011555 -0.013342" rpy="0 0 0" />
			<mass value="0.013131" />
			<inertia ixx="1.94E-06" ixy="0" ixz="0" iyy="1.93E-06" iyz="1E-07" izz="5.4E-07" />
		</inertial>
		<visual>
			<origin xyz="0 0 0" rpy="0 0 0" />
			<geometry>
				<mesh filename="meshes/L_middle_proximal.dae" />
			</geometry>
			<material name="">
				<color rgba="0.75294 0.75294 0.75294 1" />
			</material>
		</visual>
		<collision>
			<origin xyz="0 0 0" rpy="0 0 0" />
			<geometry>
				<mesh filename="meshes/L_middle_proximal.dae" />
			</geometry>
		</collision>
	</link>
	<joint name="Lmiddle_proximal" type="fixed">
		<origin xyz="0.00799999999999799 0.0145000000000034 -0.127999999999996" rpy="0 0 0" />
		<parent link="wristRollLeft" />
		<child link="L_middle_proximal" />
		<axis xyz="-1 0 0" />
	</joint>
	<link name="L_middle_distal">
		<inertial>
			<origin xyz="0 -3.933E-05 -0.015462" rpy="0 0 0" />
			<mass value="0.009059" />
			<inertia ixx="1.73E-06" ixy="0" ixz="0" iyy="1.61E-06" iyz="4E-07" izz="3.2E-07" />
		</inertial>
		<visual>
			<origin xyz="0 0 0" rpy="0 0 0" />
			<geometry>
				<mesh filename="meshes/L_middle_distal.dae" />
			</geometry>
			<material name="">
				<color rgba="0.75294 0.75294 0.75294 1" />
			</material>
		</visual>
		<collision>
			<origin xyz="0 0 0" rpy="0 0 0" />
			<geometry>
				<mesh filename="meshes/L_middle_distal.dae" />
			</geometry>
		</collision>
	</link>
	<joint name="Lmiddle_distal" type="fixed">
		<origin xyz="0 -0.0029373537056584 -0.0318649015879234" rpy="0 0 0" />
		<parent link="L_middle_proximal" />
		<child link="L_middle_distal" />
		<axis xyz="-1 0 0" />
	</joint>
	<link name="L_ring_proximal">
		<inertial>
			<origin xyz="-3.95E-06 0.0019934 -0.013131" rpy="0 0 0" />
			<mass value="0.014541" />
			<inertia ixx="1.95E-06" ixy="0" ixz="0" iyy="1.95E-06" iyz="2E-08" izz="5.4E-07" />
		</inertial>
		<visual>
			<origin xyz="0 0 0" rpy="0 0 0" />
			<geometry>
				<mesh filename="meshes/L_ring_proximal.dae" />
			</geometry>
			<material name="">
				<color rgba="0.75294 0.75294 0.75294 1" />
			</material>
		</visual>
		<collision>
			<origin xyz="0 0 0" rpy="0 0 0" />
			<geometry>
				<mesh filename="meshes/L_ring_proximal.dae" />
			</geometry>
		</collision>
	</link>
	<joint name="Lring_proximal" type="fixed">
		<origin xyz="-0.0109420472123749 0.00950000000000051 -0.119975331625557" rpy="0 0.0523598775598251 0" />
		<parent link="wristRollLeft" />
		<child link="L_ring_proximal" />
		<axis xyz="-1 0 0" />
	</joint>
	<link name="L_ring_distal">
		<inertial>
			<origin xyz="0 0.0016895 -0.015369" rpy="0 0 0" />
			<mass value="0.009059" />
			<inertia ixx="1.73E-06" ixy="0" ixz="0" iyy="1.68E-06" iyz="2.5E-07" izz="2.5E-07" />
		</inertial>
		<visual>
			<origin xyz="0 0 0" rpy="0 0 0" />
			<geometry>
				<mesh filename="meshes/L_ring_distal.dae" />
			</geometry>
			<material name="">
				<color rgba="0.75294 0.75294 0.75294 1" />
			</material>
		</visual>
		<collision>
			<origin xyz="0 0 0" rpy="0 0 0" />
			<geometry>
				<mesh filename="meshes/L_ring_distal.dae" />
			</geometry>
		</collision>
	</link>
	<joint name="Lring_distal" type="fixed">
		<origin xyz="0 -0.00111268989727942 -0.0319806491677798" rpy="0 0 0" />
		<parent link="L_ring_proximal" />
		<child link="L_ring_distal" />
		<axis xyz="-1 0 0" />
	</joint>
	<link name="L_pinky_proximal">
		<inertial>
			<origin xyz="0 0.0019104 -0.013226" rpy="0 0 0" />
			<mass value="0.013131" />
			<inertia ixx="1.94E-06" ixy="0" ixz="0" iyy="1.94E-06" iyz="2E-08" izz="5.3E-07" />
		</inertial>
		<visual>
			<origin xyz="0 0 0" rpy="0 0 0" />
			<geometry>
				<mesh filename="meshes/L_pinky_proximal.dae" />
			</geometry>
			<material name="">
				<color rgba="0.75294 0.75294 0.75294 1" />
			</material>
		</visual>
		<collision>
			<origin xyz="0 0 0" rpy="0 0 0" />
			<geometry>
				<mesh filename="meshes/L_pinky_proximal.dae" />
			</geometry>
		</collision>
	</link>
	<joint name="Lpinky_proximal" type="fixed">
		<origin xyz="-0.0301936481812983 0.00450000000000383 -0.112865830729548" rpy="0 0.122173047639558 0" />
		<parent link="wristRollLeft" />
		<child link="L_pinky_proximal" />
		<axis xyz="-1 0 0" />
	</joint>
	<link name="L_pinky_distal">
		<inertial>
			<origin xyz="1.99E-06 0.0026041 -0.010999" rpy="0 0 0" />
			<mass value="0.006939" />
			<inertia ixx="8.6E-07" ixy="0" ixz="0" iyy="8.4E-07" iyz="1E-07" izz="1.6E-07" />
		</inertial>
		<visual>
			<origin xyz="0 0 0" rpy="0 0 0" />
			<geometry>
				<mesh filename="meshes/L_pinky_distal.dae" />
			</geometry>
			<material name="">
				<color rgba="0.75294 0.75294 0.75294 1" />
			</material>
		</visual>
		<collision>
			<origin xyz="0 0 0" rpy="0 0 0" />
			<geometry>
				<mesh filename="meshes/L_pinky_distal.dae" />
			</geometry>
		</collision>
	</link>
	<joint name="Lpinky_distal" type="fixed">
		<origin xyz="0 -0.00111268989728047 -0.0319806491677798" rpy="0 0 0" />
		<parent link="L_pinky_proximal" />
		<child link="L_pinky_distal" />
		<axis xyz="-1 0 0" />
	</joint>
	<link name="shoulderPitchRight">
		<inertial>
			<origin xyz="-0.00150404 -0.02687227 0.00010766" rpy="0 0 0" />
			<mass value="0.20310000" />
			<inertia ixx="0.00017009" ixy="0.00000447" ixz="-0.00000064" iyy="0.00028895" iyz="-0.00000043" izz="0.00034374" />
		</inertial>
		<visual>
			<origin xyz="0 0 0" rpy="0 0 0" />
			<geometry>
				<mesh filename="meshes/shoulderPitchRight.dae" />
			</geometry>
			<material name="">
				<color rgba="1 1 1 1" />
			</material>
		</visual>
	</link>
	<joint name="shoulderPitch_Right" type="revolute">
		<origin xyz="0 -0.16011 0.25742" rpy="-0.34907 0 0" />
		<parent link="torso" />
		<child link="shoulderPitchRight" />
		<axis xyz="0 1 0" />
		<limit effort="65.0" lower="-3.560" upper="1.989" velocity="8.0" />
	</joint>
	<link name="shoulderRollRight">
		<inertial>
			<origin xyz="-0.02860454 -0.01104592 -0.01404986" rpy="0 0 0" />
			<mass value="0.72480000" />
			<inertia ixx="0.00090814" ixy="0.00002628" ixz="0.00003990" iyy="0.00071184" iyz="0.00025129" izz="0.00060969" />
		</inertial>
		<visual>
			<origin xyz="0 0 0" rpy="0 0 0" />
			<geometry>
				<mesh filename="meshes/shoulderRollRight.dae" />
			</geometry>
			<material name="">
				<color rgba="1 1 1 1" />
			</material>
		</visual>
		<collision>
			<origin xyz="-0.035 0 0" rpy="0 1.5708 0" />
			<geometry>
				<cylinder length="0.02" radius="0.035" />
			</geometry>
		</collision>
	</link>
	<joint name="shoulderRoll_Right" type="revolute">
		<origin xyz="0.0335 -0.0435 0" rpy="0.34907 0 0" />
		<parent link="shoulderPitchRight" />
		<child link="shoulderRollRight" />
		<axis xyz="1 0 0" />
		<limit effort="65.0" lower="-2.74" upper="0.575" velocity="8.0" />
	</joint>
	<link name="shoulderYawRight">
		<inertial>
			<origin xyz="-0.00089274 -0.00096643 -0.06980518" rpy="0 0 0" />
			<mass value="0.69630000" />
			<inertia ixx="0.00304636" ixy="-0.00000070" ixz="0.00005211" iyy="0.00297764" iyz="0.00008904" izz="0.00041751" />
		</inertial>
		<visual>
			<origin xyz="0 0 0" rpy="0 0 0" />
			<geometry>
				<mesh filename="meshes/shoulderYawRight.dae" />
			</geometry>
			<material name="">
				<color rgba="1 1 1 1" />
			</material>
		</visual>
		<collision>
			<origin xyz="0 0 -0.06" rpy="0 0 0" />
			<geometry>
				<cylinder length="0.067" radius="0.0415" />
			</geometry>
		</collision>
	</link>
	<joint name="shoulderYaw_Right" type="revolute">
		<origin xyz="-0.0335 -0.034 -0.0585" rpy="0 0 0" />
		<parent link="shoulderRollRight" />
		<child link="shoulderYawRight" />
		<axis xyz="0 0 1" />
		<limit effort="65.0" lower="-1.6" upper="1.6" velocity="8.0" />
	</joint>
	<link name="elbowRight">
		<inertial>
			<origin xyz="-0.01212328 -0.02629569 -0.02658404" rpy="0 0 0" />
			<mass value="0.85400000" />
			<inertia ixx="0.00099546" ixy="0.00002241" ixz="0.00027937" iyy="0.00111379" iyz="0.00004820" izz="0.00053993" />
		</inertial>
		<visual>
			<origin xyz="0 0 0" rpy="0 0 0" />
			<geometry>
				<mesh filename="meshes/elbowRight.dae" />
			</geometry>
			<material name="">
				<color rgba="1 1 1 1" />
			</material>
		</visual>
	</link>
	<joint name="elbow_Right" type="revolute">
		<origin xyz="0 0.0285 -0.20415" rpy="0 0 0" />
		<parent link="shoulderYawRight" />
		<child link="elbowRight" />
		<axis xyz="0 1 0" />
		<limit effort="30.0" lower="-2.0" upper="0.0" velocity="8.0" />
	</joint>
	<link name="wristYawRight">
		<inertial>
			<origin xyz="-0.00202981 -0.00013146 -0.09216894" rpy="0 0 0" />
			<mass value="0.95587832" />
			<inertia ixx="0.00256092" ixy="0.00000273" ixz="0.00003067" iyy="0.00250028" iyz="0.00002722" izz="0.00055059" />
		</inertial>
		<visual>
			<origin xyz="0 0 0" rpy="0 0 0" />
			<geometry>
				<mesh filename="meshes/wristYawRight.dae" />
			</geometry>
			<material name="">
				<color rgba="1 1 1 1" />
			</material>
		</visual>
		<collision>
			<origin xyz="0 0 -0.09" rpy="0 0 0" />
			<geometry>
				<cylinder length="0.1" radius="0.038"/>
			</geometry>
		</collision>
	</link>
	<joint name="wristYaw_Right" type="revolute">
		<origin xyz="-0.025 -0.0285 -0.0729" rpy="0 0 0" />
		<parent link="elbowRight" />
		<child link="wristYawRight" />
		<axis xyz="0 0 1" />
		<limit effort="6.4" lower="-2.617" upper="2.617" velocity="4.9218" />
	</joint>
	<link name="wristPitchRight">
		<inertial>
			<origin xyz="-0.00017580 0.00166098 -0.00002773" rpy="0 0 0" />
			<mass value="0.11963454" />
			<inertia ixx="0.00003359" ixy="0.00000002" ixz="0.00000000" iyy="0.00002690" iyz="-0.00000005" izz="0.00003977" />
		</inertial>
		<visual>
			<origin xyz="0 0 0" rpy="0 0 0" />
			<geometry>
				<mesh filename="meshes/wristPitchRight.dae" />
			</geometry>
			<material name="">
				<color rgba="1 1 1 1" />
			</material>
		</visual>
	</link>
	<joint name="wristPitch_Right" type="revolute">
		<origin xyz="0 0 -0.201699999719004" rpy="0 0 0" />
		<parent link="wristYawRight" />
		<child link="wristPitchRight" />
		<axis xyz="0 1 0" />
		<limit effort="6.4" lower="-0.907" upper="0.907" velocity="4.9218" />
	</joint>
	<link name="wristRollRight">
		<inertial>
			<origin xyz="-0.00030616 -0.0086183 -0.066344" rpy="0 0 0" />
			<mass value="0.35816" />
			<inertia ixx="0.00032078" ixy="-1.18E-05" ixz="-4.53E-06" iyy="0.00043005" iyz="2.137E-05" izz="0.00018497" />
		</inertial>
		<visual>
			<origin xyz="0 0 0" rpy="0 0 0" />
			<geometry>
				<mesh filename="meshes/wristRollRight.dae" />
			</geometry>
			<material name="">
				<color rgba="0.75294 0.75294 0.75294 1" />
			</material>
		</visual>
		<collision>
			<origin xyz="0 0 0" rpy="0 0 0" />
			<geometry>
				<mesh filename="meshes/wristRollRight.dae" />
			</geometry>
		</collision>
	</link>
	<joint name="wristRoll_Right" type="revolute">
		<origin xyz="0 0 0" rpy="0 0 0" />
		<parent link="wristPitchRight" />
		<child link="wristRollRight" />
		<axis xyz="1 0 0" />
		<limit effort="6.4" lower="-0.907" upper="0.907" velocity="4.9218" />
	</joint>
	<link name="R_thumb_proximal_base">
		<inertial>
			<origin xyz="0.0043163 -0.00026726 -0.0014188" rpy="0 0 0" />
			<mass value="0.0089319" />
			<inertia ixx="3.1E-07" ixy="8E-08" ixz="-6E-08" iyy="5.5E-07" iyz="-1E-08" izz="4.6E-07" />
		</inertial>
		<visual>
			<origin xyz="0 0 0" rpy="0 0 0" />
			<geometry>
				<mesh filename="meshes/R_thumb_proximal_base.dae" />
			</geometry>
			<material name="">
				<color rgba="0.75294 0.75294 0.75294 1" />
			</material>
		</visual>
		<collision>
			<origin xyz="0 0 0" rpy="0 0 0" />
			<geometry>
				<mesh filename="meshes/R_thumb_proximal_base.dae" />
			</geometry>
		</collision>
	</link>
	<joint name="Rthumb_proximal_base" type="fixed">
		<origin xyz="0.0245 0.01 -0.047" rpy="0 0 0" />
		<parent link="wristRollRight" />
		<child link="R_thumb_proximal_base" />
		<axis xyz="0 0 -1" />
	</joint>
	<link name="R_thumb_proximal">
		<inertial>
			<origin xyz="0.023697 0 -0.014672" rpy="0 0 0" />
			<mass value="0.061584" />
			<inertia ixx="1.171E-05" ixy="0" ixz="-5.75E-06" iyy="2.013E-05" iyz="0" izz="1.139E-05" />
		</inertial>
		<visual>
			<origin xyz="0 0 0" rpy="0 0 0" />
			<geometry>
				<mesh filename="meshes/R_thumb_proximal.dae" />
			</geometry>
			<material name="">
				<color rgba="0.75294 0.75294 0.75294 1" />
			</material>
		</visual>
		<collision>
			<origin xyz="0 0 0" rpy="0 0 0" />
			<geometry>
				<mesh filename="meshes/R_thumb_proximal.dae" />
			</geometry>
		</collision>
	</link>
	<joint name="Rthumb_proximal" type="fixed">
		<origin xyz="0.011954 0.0010497 0" rpy="0 0 0.087585" />
		<parent link="R_thumb_proximal_base" />
		<child link="R_thumb_proximal" />
		<axis xyz="0 1 0" />
	</joint>
	<link name="R_thumb_intermediate">
		<inertial>
			<origin xyz="0.0097313 0 -0.0026647" rpy="0 0 0" />
			<mass value="0.015383" />
			<inertia ixx="1.42E-06" ixy="0" ixz="-3.9E-07" iyy="1.72E-06" iyz="0" izz="1E-06" />
		</inertial>
		<visual>
			<origin xyz="0 0 0" rpy="0 0 0" />
			<geometry>
				<mesh filename="meshes/R_thumb_intermediate.dae" />
			</geometry>
			<material name="">
				<color rgba="0.75294 0.75294 0.75294 1" />
			</material>
		</visual>
		<collision>
			<origin xyz="0 0 0" rpy="0 0 0" />
			<geometry>
				<mesh filename="meshes/R_thumb_intermediate.dae" />
			</geometry>
		</collision>
	</link>
	<joint name="Rthumb_intermediate" type="fixed">
		<origin xyz="0.044289 0 -0.037663" rpy="0 0 0" />
		<parent link="R_thumb_proximal" />
		<child link="R_thumb_intermediate" />
		<axis xyz="0 1 0" />
	</joint>
	<link name="R_thumb_distal">
		<inertial>
			<origin xyz="0.0071415 1.39E-06 -0.0068941" rpy="0 0 0" />
			<mass value="0.010437" />
			<inertia ixx="7.6E-07" ixy="0" ixz="-2E-07" iyy="8.6E-07" iyz="0" izz="5.2E-07" />
		</inertial>
		<visual>
			<origin xyz="0 0 0" rpy="0 0 0" />
			<geometry>
				<mesh filename="meshes/R_thumb_distal.dae" />
			</geometry>
			<material name="">
				<color rgba="0.75294 0.75294 0.75294 1" />
			</material>
		</visual>
		<collision>
			<origin xyz="0 0 0" rpy="0 0 0" />
			<geometry>
				<mesh filename="meshes/R_thumb_distal.dae" />
			</geometry>
		</collision>
	</link>
	<joint name="Rthumb_distal" type="fixed">
		<origin xyz="0.016468 0 -0.015461" rpy="0 0 0" />
		<parent link="R_thumb_intermediate" />
		<child link="R_thumb_distal" />
		<axis xyz="0 1 0" />
	</joint>
	<link name="R_index_proximal">
		<inertial>
			<origin xyz="0 -0.0019982 -0.013117" rpy="0 0 0" />
			<mass value="0.014541" />
			<inertia ixx="1.95E-06" ixy="0" ixz="0" iyy="1.95E-06" iyz="-2E-08" izz="5.4E-07" />
		</inertial>
		<visual>
			<origin xyz="0 0 0" rpy="0 0 0" />
			<geometry>
				<mesh filename="meshes/R_index_proximal.dae" />
			</geometry>
			<material name="">
				<color rgba="0.75294 0.75294 0.75294 1" />
			</material>
		</visual>
		<collision>
			<origin xyz="0 0 0" rpy="0 0 0" />
			<geometry>
				<mesh filename="meshes/R_index_proximal.dae" />
			</geometry>
		</collision>
	</link>
	<joint name="Rindex_proximal" type="fixed">
		<origin xyz="0.026942 -0.0095 -0.11498" rpy="0 -0.05236 0" />
		<parent link="wristRollRight" />
		<child link="R_index_proximal" />
		<axis xyz="1 0 0" />
	</joint>
	<link name="R_index_distal">
		<inertial>
			<origin xyz="0 -0.0016894 -0.01537" rpy="0 0 0" />
			<mass value="0.009059" />
			<inertia ixx="1.73E-06" ixy="0" ixz="0" iyy="1.68E-06" iyz="-2.5E-07" izz="2.5E-07" />
		</inertial>
		<visual>
			<origin xyz="0 0 0" rpy="0 0 0" />
			<geometry>
				<mesh filename="meshes/R_index_distal.dae" />
			</geometry>
			<material name="">
				<color rgba="0.75294 0.75294 0.75294 1" />
			</material>
		</visual>
		<collision>
			<origin xyz="0 0 0" rpy="0 0 0" />
			<geometry>
				<mesh filename="meshes/R_index_distal.dae" />
			</geometry>
		</collision>
	</link>
	<joint name="Rindex_distal" type="fixed">
		<origin xyz="0 0.0011127 -0.031981" rpy="0 0 0" />
		<parent link="R_index_proximal" />
		<child link="R_index_distal" />
		<axis xyz="1 0 0" />
	</joint>
	<link name="R_middle_proximal">
		<inertial>
			<origin xyz="0 -0.0011555 -0.013342" rpy="0 0 0" />
			<mass value="0.013131" />
			<inertia ixx="1.94E-06" ixy="0" ixz="0" iyy="1.93E-06" iyz="-1E-07" izz="5.4E-07" />
		</inertial>
		<visual>
			<origin xyz="0 0 0" rpy="0 0 0" />
			<geometry>
				<mesh filename="meshes/R_middle_proximal.dae" />
			</geometry>
			<material name="">
				<color rgba="0.75294 0.75294 0.75294 1" />
			</material>
		</visual>
		<collision>
			<origin xyz="0 0 0" rpy="0 0 0" />
			<geometry>
				<mesh filename="meshes/R_middle_proximal.dae" />
			</geometry>
		</collision>
	</link>
	<joint name="Rmiddle_proximal" type="fixed">
		<origin xyz="0.008 -0.0145 -0.128" rpy="0 0 0" />
		<parent link="wristRollRight" />
		<child link="R_middle_proximal" />
		<axis xyz="1 0 0" />
	</joint>
	<link name="R_middle_distal">
		<inertial>
			<origin xyz="0 3.955E-05 -0.015462" rpy="0 0 0" />
			<mass value="0.009059" />
			<inertia ixx="1.73E-06" ixy="0" ixz="0" iyy="1.61E-06" iyz="-4E-07" izz="3.2E-07" />
		</inertial>
		<visual>
			<origin xyz="0 0 0" rpy="0 0 0" />
			<geometry>
				<mesh filename="meshes/R_middle_distal.dae" />
			</geometry>
			<material name="">
				<color rgba="0.75294 0.75294 0.75294 1" />
			</material>
		</visual>
		<collision>
			<origin xyz="0 0 0" rpy="0 0 0" />
			<geometry>
				<mesh filename="meshes/R_middle_distal.dae" />
			</geometry>
		</collision>
	</link>
	<joint name="Rmiddle_distal" type="fixed">
		<origin xyz="0 0.0029374 -0.031865" rpy="0 0 0" />
		<parent link="R_middle_proximal" />
		<child link="R_middle_distal" />
		<axis xyz="1 0 0" />
	</joint>
	<link name="R_ring_proximal">
		<inertial>
			<origin xyz="0 -0.0019982 -0.013117" rpy="0 0 0" />
			<mass value="0.014541" />
			<inertia ixx="1.95E-06" ixy="0" ixz="0" iyy="1.95E-06" iyz="-2E-08" izz="5.4E-07" />
		</inertial>
		<visual>
			<origin xyz="0 0 0" rpy="0 0 0" />
			<geometry>
				<mesh filename="meshes/R_ring_proximal.dae" />
			</geometry>
			<material name="">
				<color rgba="0.75294 0.75294 0.75294 1" />
			</material>
		</visual>
		<collision>
			<origin xyz="0 0 0" rpy="0 0 0" />
			<geometry>
				<mesh filename="meshes/R_ring_proximal.dae" />
			</geometry>
		</collision>
	</link>
	<joint name="Rring_proximal" type="fixed">
		<origin xyz="-0.010942 -0.0095 -0.11998" rpy="0 0.05236 0" />
		<parent link="wristRollRight" />
		<child link="R_ring_proximal" />
		<axis xyz="1 0 0" />
	</joint>
	<link name="R_ring_distal">
		<inertial>
			<origin xyz="0 -0.0016894 -0.01537" rpy="0 0 0" />
			<mass value="0.009059" />
			<inertia ixx="1.73E-06" ixy="0" ixz="0" iyy="1.68E-06" iyz="-2.5E-07" izz="2.5E-07" />
		</inertial>
		<visual>
			<origin xyz="0 0 0" rpy="0 0 0" />
			<geometry>
				<mesh filename="meshes/R_ring_distal.dae" />
			</geometry>
			<material name="">
				<color rgba="0.75294 0.75294 0.75294 1" />
			</material>
		</visual>
		<collision>
			<origin xyz="0 0 0" rpy="0 0 0" />
			<geometry>
				<mesh filename="meshes/R_ring_distal.dae" />
			</geometry>
		</collision>
	</link>
	<joint name="Rring_distal" type="fixed">
		<origin xyz="0 0.0011127 -0.031981" rpy="0 0 0" />
		<parent link="R_ring_proximal" />
		<child link="R_ring_distal" />
		<axis xyz="1 0 0" />
	</joint>
	<link name="R_pinky_proximal">
		<inertial>
			<origin xyz="0 -0.0019105 -0.013226" rpy="0 0 0" />
			<mass value="0.013131" />
			<inertia ixx="1.94E-06" ixy="0" ixz="0" iyy="1.94E-06" iyz="-2E-08" izz="5.3E-07" />
		</inertial>
		<visual>
			<origin xyz="0 0 0" rpy="0 0 0" />
			<geometry>
				<mesh filename="meshes/R_pinky_proximal.dae" />
			</geometry>
			<material name="">
				<color rgba="0.75294 0.75294 0.75294 1" />
			</material>
		</visual>
		<collision>
			<origin xyz="0 0 0" rpy="0 0 0" />
			<geometry>
				<mesh filename="meshes/R_pinky_proximal.dae" />
			</geometry>
		</collision>
	</link>
	<joint name="Rpinky_proximal" type="fixed">
		<origin xyz="-0.030194 -0.0045 -0.11287" rpy="0 0.12217 0" />
		<parent link="wristRollRight" />
		<child link="R_pinky_proximal" />
		<axis xyz="1 0 0" />
	</joint>
	<link name="R_pinky_distal">
		<inertial>
			<origin xyz="2.01E-06 -0.0026042 -0.010999" rpy="0 0 0" />
			<mass value="0.006939" />
			<inertia ixx="8.6E-07" ixy="0" ixz="0" iyy="8.4E-07" iyz="-1E-07" izz="1.6E-07" />
		</inertial>
		<visual>
			<origin xyz="0 0 0" rpy="0 0 0" />
			<geometry>
				<mesh filename="meshes/R_pinky_distal.dae" />
			</geometry>
			<material name="">
				<color rgba="0.75294 0.75294 0.75294 1" />
			</material>
		</visual>
		<collision>
			<origin xyz="0 0 0" rpy="0 0 0" />
			<geometry>
				<mesh filename="meshes/R_pinky_distal.dae" />
			</geometry>
		</collision>
	</link>
	<joint name="Rpinky_distal" type="fixed">
		<origin xyz="0 0.0011127 -0.031981" rpy="0 0 0" />
		<parent link="R_pinky_proximal" />
		<child link="R_pinky_distal" />
		<axis xyz="1 0 0" />
	</joint>
</robot>
