<?xml version="1.1" encoding="utf-8"?>
<!-- =================================================================================== -->
<!-- Copyright 2024 PNDbotics, https://www.pndbotics.com/ -->
<!-- =================================================================================== -->
<!-- This file contains the description of the adam lite robot. -->
<robot name="adam_inspire">
	<!-- <link name="world"/> -->
	<link name="pelvis">
		<inertial>
			<origin xyz="-0.00120281  -0.00000119 -0.00802155" rpy="0 0 0" />
			<mass value="10.18730021" />
			<inertia ixx="0.06839529" ixy="-0.00000995" ixz="-0.00004308" iyy="0.03753230" iyz="-0.00000105" izz="0.07519708" />
		</inertial>
		<visual>
			<origin xyz="0 0 0" rpy="0 0 0" />
			<geometry>
				<mesh filename="../meshes/pelvis.dae" />
			</geometry>
			<material name="">
				<color rgba="1 1 1 1" />
			</material>
		</visual>
		<collision>
			<origin xyz="0.0 0.0 0" rpy="1.57 0 0" />
			<geometry>
				<cylinder length="0.1" radius="0.1" />
			</geometry>
		</collision>
	</link>
	<joint name="imu_joint" type="fixed">
		<parent link="pelvis" />
		<child link="imu_link" />
		<origin rpy="0 0 0" xyz="0 0 0" />
	</joint>
	<link name="imu_link">
		<inertial>
			<mass value="0.001" />
			<origin rpy="0 0 0" xyz="0 0 0" />
			<inertia ixx="0.0001" ixy="0" ixz="0" iyy="0.0001" iyz="0" izz="0.0001" />
		</inertial>
		<visual>
			<origin rpy="0 0 0" xyz="0 0 0" />
			<geometry>
				<mesh filename="../meshes/vn100-0001.dae" />
			</geometry>
		</visual>
	</link>
	<!--
	<joint name="floating_joint" type="floating">
	<parent link="world"/>
	<child link="pelvis"/>
	<origin xyz="0 0 0" rpy="0 0 0"/>
	<axis xyz="0 0 0 1 0 0" />
	<axis xyz="0 0 0 0 1 0" />
	<axis xyz="0 0 0 0 0 1" />
	<axis xyz="1 0 0" />
	<axis xyz="0 1 0" />
	<axis xyz="0 0 1" />
	</joint>
	-->
	<link name="hipPitchLeft">
		<inertial>
			<origin xyz="-0.05818187 0.05889478 -0.00031205" rpy="0 0 0" />
			<mass value="2.15124786" />
			<inertia ixx="0.00385847" ixy="-0.00094455" ixz="0.00002598" iyy="0.00440973" iyz="0.00002828" izz="0.00508085" />
		</inertial>
		<visual>
			<origin xyz="0 0 0" rpy="0 0 0" />
			<geometry>
				<mesh filename="../meshes/hipPitchLeft.dae" />
			</geometry>
			<material name="">
				<color rgba="1 1 1 1" />
			</material>
		</visual>
	</link>
	<joint name="hipPitch_Left" type="revolute">
		<origin xyz="0 0.096192 -0.033241" rpy="-0.61087 0 0" />
		<parent link="pelvis" />
		<child link="hipPitchLeft" />
		<axis xyz="0 1 0" />
		<limit effort="230.0" lower="-2.164" upper="2.164" velocity="15.0" />
	</joint>
	<link name="hipRollLeft">
		<inertial>
			<origin xyz="0.03995412 -0.00011618 -0.01102103" rpy="0 0 0" />
			<mass value="1.29421887" />
			<inertia ixx="0.00134168" ixy="-0.00000431" ixz="-0.00006007" iyy="0.00137070" iyz="-0.00001695" izz="0.00144577" />
		</inertial>
		<visual>
			<origin xyz="0 0 0" rpy="0 0 0" />
			<geometry>
				<mesh filename="../meshes/hipRollLeft.dae" />
			</geometry>
			<material name="">
				<color rgba="1 1 1 1" />
			</material>
		</visual>
	</link>
	<joint name="hipRoll_Left" type="revolute">
		<origin xyz="-0.0255 0.069 0" rpy="0.61087 0 0" />
		<parent link="hipPitchLeft" />
		<child link="hipRollLeft" />
		<axis xyz="1 0 0" />
		<limit effort="160.0" lower="-0.733" upper="1.605" velocity="8.0" />
	</joint>
	<link name="thighLeft">
		<inertial>
			<origin xyz="0.00331195 -0.01112470 -0.13519832" rpy="0 0 0" />
			<mass value="6.64749717" />
			<inertia ixx="0.05688222" ixy="-0.00031813" ixz="-0.00156531" iyy="0.06217155" iyz="0.00531838" izz="0.01520394" />
		</inertial>
		<visual>
			<origin xyz="0 0 0" rpy="0 0 0" />
			<geometry>
				<mesh filename="../meshes/thighLeft.dae" />
			</geometry>
			<material name="">
				<color rgba="1 1 1 1" />
			</material>
		</visual>
		<collision>
			<origin xyz="0.0 -0.01 -0.13" rpy="-0.174533 0 0" />
			<geometry>
				<cylinder length="0.08" radius="0.06" />
			</geometry>
		</collision>
	</link>
	<joint name="hipYaw_Left" type="revolute">
		<origin xyz="0.044 0 -0.0525" rpy="0 0 0" />
		<parent link="hipRollLeft" />
		<child link="thighLeft" />
		<axis xyz="0 0 1" />
		<limit effort="105" lower="-0.785" upper="0.785" velocity="8.0" />
	</joint>
	<link name="shinLeft">
		<inertial>
			<origin xyz="-0.00080913 0.00097265 -0.14540818" rpy="0 0 0" />
			<mass value="2.19866469" />
			<inertia ixx="0.01932815" ixy="-0.00001127" ixz="0.00022012" iyy="0.01940985" iyz="0.00008606" izz="0.00136828" />
		</inertial>
		<visual>
			<origin xyz="0 0 0" rpy="0 0 0" />
			<geometry>
				<mesh filename="../meshes/shinLeft.dae" />
			</geometry>
			<material name="">
				<color rgba="1 1 1 1" />
			</material>
		</visual>
		<collision>
			<origin xyz="0.0 0.0 -0.17" rpy="0 0 0" />
			<geometry>
				<cylinder length="0.22" radius="0.04" />
			</geometry>
		</collision>
	</link>
	<joint name="kneePitch_Left" type="revolute">
		<origin xyz="0 -0.0355 -0.369" rpy="0 0 0" />
		<parent link="thighLeft" />
		<child link="shinLeft" />
		<axis xyz="0 1 0" />
		<limit effort="230.0" lower="0.052" upper="2.391" velocity="15.0" />
	</joint>
	<link name="anklePitchLeft">
		<inertial>
			<origin xyz="0.00000000 0.00000000 0.00000000" rpy="0 0 0" />
			<mass value="0.03100000" />
			<inertia ixx="0.00000323" ixy="0.00000000" ixz="0.00000000" iyy="0.00000323" iyz="0.00000000" izz="0.00000210" />
		</inertial>
		<visual>
			<origin xyz="0 0 0" rpy="0 0 0" />
			<geometry>
				<mesh filename="../meshes/anklePitchLeft.dae" />
			</geometry>
			<material name="">
				<color rgba="1 1 1 1" />
			</material>
		</visual>
	</link>
	<joint name="anklePitch_Left" type="revolute">
		<origin xyz="0 0 -0.37" rpy="0 0 0" />
		<parent link="shinLeft" />
		<child link="anklePitchLeft" />
		<axis xyz="0 1 0" />
		<limit effort="40.0" lower="-1.0" upper="0.35" velocity="20.0" />
	</joint>
	<link name="toeLeft">
		<inertial>
			<origin xyz="0.03700657 -0.00002063 -0.04198684" rpy="0 0 0" />
			<mass value="0.47580000" />
			<inertia ixx="0.00028492" ixy="0.00001326" ixz="-0.00012023" iyy="0.00152181" iyz="0.00000143" izz="0.00158187" />
		</inertial>
		<visual>
			<origin xyz="0 0 0" rpy="0 0 0" />
			<geometry>
				<mesh filename="../meshes/toeLeft.dae" />
			</geometry>
			<material name="">
				<color rgba="0.752941176470588 0.752941176470588 0.752941176470588 1" />
			</material>
		</visual>
		<collision name="toe_left">
			<origin rpy="0 0 0" xyz="0 0 0" />
			<geometry>
				<mesh filename="../meshes/toeLeft.dae" />
			</geometry>
		</collision>
	</link>
	<joint name="ankleRoll_Left" type="revolute">
		<origin xyz="0 0 0" rpy="0 0 0" />
		<parent link="anklePitchLeft" />
		<child link="toeLeft" />
		<axis xyz="1 0 0" />
		<limit effort="12.0" lower="-0.3491" upper="0.3491" velocity="20.0" />
	</joint>
	<link name="hipPitchRight">
		<inertial>
			<origin xyz="-0.05818164 -0.05886958 -0.00032981" rpy="0 0 0" />
			<mass value="2.15124254" />
			<inertia ixx="0.00385735" ixy="0.00094210" ixz="0.00002770" iyy="0.00440670" iyz="-0.00002677" izz="0.00508280" />
		</inertial>
		<visual>
			<origin xyz="0 0 0" rpy="0 0 0" />
			<geometry>
				<mesh filename="../meshes/hipPitchRight.dae" />
			</geometry>
			<material name="">
				<color rgba="1 1 1 1" />
			</material>
		</visual>
	</link>
	<joint name="hipPitch_Right" type="revolute">
		<origin xyz="0 -0.096192 -0.033241" rpy="0.61087 0 0" />
		<parent link="pelvis" />
		<child link="hipPitchRight" />
		<axis xyz="0 1 0" />
		<limit effort="230.0" lower="-2.164" upper="2.164" velocity="15.0" />
	</joint>
	<link name="hipRollRight">
		<inertial>
			<origin xyz="0.03988167 0.00011594 -0.01102087" rpy="0 0 0" />
			<mass value="1.29422777" />
			<inertia ixx="0.00134170" ixy="0.00000379" ixz="-0.00006269" iyy="0.00136997" iyz="0.00001693" izz="0.00144502" />
		</inertial>
		<visual>
			<origin xyz="0 0 0" rpy="0 0 0" />
			<geometry>
				<mesh filename="../meshes/hipRollRight.dae" />
			</geometry>
			<material name="">
				<color rgba="1 1 1 1" />
			</material>
		</visual>
	</link>
	<joint name="hipRoll_Right" type="revolute">
		<origin xyz="-0.0255 -0.069 0" rpy="-0.61087 0 0" />
		<parent link="hipPitchRight" />
		<child link="hipRollRight" />
		<axis xyz="1 0 0" />
		<limit effort="160.0" lower="-1.605" upper="0.733" velocity="8.0" />
	</joint>
	<link name="thighRight">
		<inertial>
			<origin xyz="0.00332701 0.01110269 -0.13528959" rpy="0 0 0" />
			<mass value="6.64754534" />
			<inertia ixx="0.05714386" ixy="0.00030277" ixz="-0.00153883" iyy="0.06243248" iyz="-0.00531134" izz="0.01517531" />
		</inertial>
		<visual>
			<origin xyz="0 0 0" rpy="0 0 0" />
			<geometry>
				<mesh filename="../meshes/thighRight.dae" />
			</geometry>
			<material name="">
				<color rgba="1 1 1 1" />
			</material>
		</visual>
		<collision>
			<origin xyz="0.0 0.01 -0.13" rpy="0 0 0" />
			<geometry>
				<cylinder length="0.08" radius="0.06" />
			</geometry>
		</collision>
	</link>
	<joint name="hipYaw_Right" type="revolute">
		<origin xyz="0.044 0 -0.0525" rpy="0 0 0" />
		<parent link="hipRollRight" />
		<child link="thighRight" />
		<axis xyz="0 0 1" />
		<limit effort="105" lower="-0.785" upper="0.785" velocity="8.0" />
	</joint>
	<link name="shinRight">
		<inertial>
			<origin xyz="-0.00079979 -0.00097288 -0.14635087" rpy="0 0 0" />
			<mass value="2.20809154" />
			<inertia ixx="0.01979830" ixy="0.00001096" ixz="0.00021758" iyy="0.01987660" iyz="-0.00009064" izz="0.00137192" />
		</inertial>
		<visual>
			<origin xyz="0 0 0" rpy="0 0 0" />
			<geometry>
				<mesh filename="../meshes/shinRight.dae" />
			</geometry>
			<material name="">
				<color rgba="1 1 1 1" />
			</material>
		</visual>
		<collision>
			<origin xyz="0.0 0.0 -0.17" rpy="0 0 0" />
			<geometry>
				<cylinder length="0.22" radius="0.04" />
			</geometry>
		</collision>
	</link>
	<joint name="kneePitch_Right" type="revolute">
		<origin xyz="0 0.0355 -0.369" rpy="0 0 0" />
		<parent link="thighRight" />
		<child link="shinRight" />
		<axis xyz="0 1 0" />
		<limit effort="230.0" lower="0.052" upper="2.391" velocity="15.0" />
	</joint>
	<link name="anklePitchRight">
		<inertial>
			<origin xyz="0.00000000 0.00000000 0.00000000" rpy="0 0 0" />
			<mass value="0.03100000" />
			<inertia ixx="0.00000323" ixy="0.00000000" ixz="0.00000000" iyy="0.00000323" iyz="0.00000000" izz="0.00000210" />
		</inertial>
		<visual>
			<origin xyz="0 0 0" rpy="0 0 0" />
			<geometry>
				<mesh filename="../meshes/anklePitchRight.dae" />
			</geometry>
			<material name="">
				<color rgba="0.752941176470588 0.752941176470588 0.752941176470588 1" />
			</material>
		</visual>
	</link>
	<joint name="anklePitch_Right" type="revolute">
		<origin xyz="0 0 -0.37" rpy="0 0 0" />
		<parent link="shinRight" />
		<child link="anklePitchRight" />
		<axis xyz="0 1 0" />
		<limit effort="40.0" lower="-1.0" upper="0.35" velocity="20.0" />
	</joint>
	<link name="toeRight">
		<inertial>
			<origin xyz="0.03700297 0.00002151 -0.04197563" rpy="0 0 0" />
			<mass value="0.47580000" />
			<inertia ixx="0.00028522" ixy="-0.00001320" ixz="-0.00012034" iyy="0.00152191" iyz="-0.00000143" izz="0.00158164" />
		</inertial>
		<visual>
			<origin xyz="0 0 0" rpy="0 0 0" />
			<geometry>
				<mesh filename="../meshes/toeRight.dae" />
			</geometry>
			<material name="">
				<color rgba="0.752941176470588 0.752941176470588 0.752941176470588 1" />
			</material>
		</visual>
		<collision name="toe_right">
			<origin rpy="0 0 0" xyz="0 0 0" />
			<geometry>
				<mesh filename="../meshes/toeRight.dae" />
			</geometry>
		</collision>
	</link>
	<joint name="ankleRoll_Right" type="revolute">
		<origin xyz="0 0 0" rpy="0 0 0" />
		<parent link="anklePitchRight" />
		<child link="toeRight" />
		<axis xyz="1 0 0" />
		<limit effort="12.0" lower="-0.3491" upper="0.3491" velocity="20.0" />
	</joint>
	<link name="waistRoll">
		<inertial>
			<origin xyz="0.00212014 0.00212051 0.03999987" rpy="0 0 0" />
			<mass value="2.18430742" />
			<inertia ixx="0.00490282" ixy="-0.00000839" ixz="-0.00014940" iyy="0.00490290" iyz="0.00014939" izz="0.00201818" />
		</inertial>
		<visual>
			<origin xyz="0 0 0" rpy="0 0 0" />
			<geometry>
				<mesh filename="../meshes/waistRoll.dae" />
			</geometry>
			<material name="">
				<color rgba="1 1 1 1" />
			</material>
		</visual>
	</link>
	<joint name="waistRoll" type="revolute">
		<origin xyz="0 0 0.044" rpy="0 0 0" />
		<parent link="pelvis" />
		<child link="waistRoll" />
		<axis xyz="1 0 0" />
		<limit effort="110" lower="-0.226" upper="0.226" velocity="8.0" />
	</joint>
	<link name="waistPitch">
		<inertial>
			<origin xyz="-0.00066627 0.00070478 0.02506554" rpy="0 0 0" />
			<mass value="0.49870000" />
			<inertia ixx="0.00136060" ixy="0.00000019" ixz="-0.00000061" iyy="0.00061064" iyz="-0.00002570" izz="0.00144067" />
		</inertial>
		<visual>
			<origin xyz="0 0 0" rpy="0 0 0" />
			<geometry>
				<mesh filename="../meshes/waistPitch.dae" />
			</geometry>
			<material name="">
				<color rgba="1 1 1 1" />
			</material>
		</visual>
	</link>
	<joint name="waistPitch" type="revolute">
		<origin xyz="0 0 0.08" rpy="0 0 0" />
		<parent link="waistRoll" />
		<child link="waistPitch" />
		<axis xyz="0 1 0" />
		<limit effort="110" lower="-0.785" upper="1.308" velocity="8.0" />
	</joint>
	<link name="torso">
		<inertial>
			<origin xyz="0.00080019 -0.00003149 0.18300318" rpy="0 0 0" />
			<mass value="13.28595962" />
			<inertia ixx="0.19892857" ixy="0.00002898" ixz="0.00372210" iyy="0.16115382" iyz="-0.00010404" izz="0.07256954" />
		</inertial>
		<visual>
			<origin xyz="0 0 0" rpy="0 0 0" />
			<geometry>
				<mesh filename="../meshes/torso.dae" />
			</geometry>
			<material name="">
				<color rgba="0.752941176470588 0.752941176470588 0.752941176470588 1" />
			</material>
		</visual>
		<collision>
			<origin xyz="0 0 0.15" rpy="0 0 0" />
			<geometry>
				<sphere radius="0.13" />
			</geometry>
		</collision>
	</link>
	<joint name="waistYaw" type="revolute">
		<origin xyz="0 0.0005 0.053" rpy="0 0 0" />
		<parent link="waistPitch" />
		<child link="torso" />
		<axis xyz="0 0 1" />
		<limit effort="110" lower="-0.78" upper="0.78" velocity="8.0" />
	</joint>
	<link name="shoulderPitchLeft">
		<inertial>
			<origin xyz="-0.00150404 0.02688841 0.00010848" rpy="0 0 0" />
			<mass value="0.20310000" />
			<inertia ixx="0.00017020" ixy="-0.00000461" ixz="-0.00000064" iyy="0.00028895" iyz="0.00000042" izz="0.00034385" />
		</inertial>
		<visual>
			<origin xyz="0 0 0" rpy="0 0 0" />
			<geometry>
				<mesh filename="../meshes/shoulderPitchLeft.dae" />
			</geometry>
			<material name="">
				<color rgba="1 1 1 1" />
			</material>
		</visual>
	</link>
	<joint name="shoulderPitch_Left" type="revolute">
		<origin xyz="0 0.16011 0.25742" rpy="0.34907 0 0" />
		<parent link="torso" />
		<child link="shoulderPitchLeft" />
		<axis xyz="0 1 0" />
		<limit effort="65.0" lower="-3.560" upper="1.989" velocity="8.0" />
	</joint>
	<link name="shoulderRollLeft">
		<inertial>
			<origin xyz="-0.02860447 0.01104245 -0.01405309" rpy="0 0 0" />
			<mass value="0.72480000" />
			<inertia ixx="0.00090812" ixy="-0.00002621" ixz="0.00003997" iyy="0.00071197" iyz="-0.00025129" izz="0.00060954" />
		</inertial>
		<visual>
			<origin xyz="0 0 0" rpy="0 0 0" />
			<geometry>
				<mesh filename="../meshes/shoulderRollLeft.dae" />
			</geometry>
			<material name="">
				<color rgba="1 1 1 1" />
			</material>
		</visual>
		<collision>
			<origin xyz="-0.035 0 0" rpy="0 1.5708 0" />
			<geometry>
				<cylinder length="0.02" radius="0.035" />
			</geometry>
		</collision>
	</link>
	<joint name="shoulderRoll_Left" type="revolute">
		<origin xyz="0.0335 0.0435 0" rpy="-0.34907 0 0" />
		<parent link="shoulderPitchLeft" />
		<child link="shoulderRollLeft" />
		<axis xyz="1 0 0" />
		<limit effort="65.0" lower="-0.575" upper="2.74" velocity="8.0" />
	</joint>
	<link name="shoulderYawLeft">
		<inertial>
			<origin xyz="-0.00069813 0.00102049 -0.06842313" rpy="0 0 0" />
			<mass value="0.69630000" />
			<inertia ixx="0.00317887" ixy="0.00000059" ixz="0.00005528" iyy="0.00310433" iyz="-0.00009472" izz="0.00039452" />
		</inertial>
		<visual>
			<origin xyz="0 0 0" rpy="0 0 0" />
			<geometry>
				<mesh filename="../meshes/shoulderYawLeft.dae" />
			</geometry>
			<material name="">
				<color rgba="1 1 1 1" />
			</material>
		</visual>
		<collision>
			<origin xyz="0 0 -0.06" rpy="0 0 0" />
			<geometry>
				<cylinder length="0.067" radius="0.0415" />
			</geometry>
		</collision>
	</link>
	<joint name="shoulderYaw_Left" type="revolute">
		<origin xyz="-0.0335 0.034 -0.0585" rpy="0 0 0" />
		<parent link="shoulderRollLeft" />
		<child link="shoulderYawLeft" />
		<axis xyz="0 0 1" />
		<limit effort="65.0" lower="-1.6" upper="1.6" velocity="8.0" />
	</joint>
	<link name="elbowLeft">
		<inertial>
			<origin xyz="-0.01212328 0.02629569 -0.02658404" rpy="0 0 0" />
			<mass value="0.85400000" />
			<inertia ixx="0.00072987" ixy="-0.00001380" ixz="0.00015644" iyy="0.00080410" iyz="-0.00002763" izz="0.00047565" />
		</inertial>
		<visual>
			<origin xyz="0 0 0" rpy="0 0 0" />
			<geometry>
				<mesh filename="../meshes/elbowLeft.dae" />
			</geometry>
			<material name="">
				<color rgba="1 1 1 1" />
			</material>
		</visual>
	</link>
	<joint name="elbow_Left" type="revolute">
		<origin xyz="0 -0.0285 -0.20415" rpy="0 0 0" />
		<parent link="shoulderYawLeft" />
		<child link="elbowLeft" />
		<axis xyz="0 1 0" />
		<limit effort="30.0" lower="-2.0" upper="0.0" velocity="8.0" />
	</joint>
	<link name="wristYawLeft">
		<inertial>
			<origin xyz="-0.00202981 0.00013146 -0.09216894" rpy="0 0 0" />
			<mass value="0.95587869" />
			<inertia ixx="0.00256138" ixy="-0.00000268" ixz="0.00003060" iyy="0.00250125" iyz="-0.00002660" izz="0.00055105" />
		</inertial>
		<visual>
			<origin xyz="0 0 0" rpy="0 0 0" />
			<geometry>
				<mesh filename="../meshes/wristYawLeft.dae" />
			</geometry>
			<material name="">
				<color rgba="1 1 1 1" />
			</material>
		</visual>
		<collision>
			<origin xyz="0 0 -0.09" rpy="0 0 0" />
			<geometry>
				<cylinder length="0.1" radius="0.038"/>
			</geometry>
		</collision>
	</link>
	<joint name="wristYaw_Left" type="fixed">
		<origin xyz="-0.025 0.0285 -0.0729" rpy="0 0 0" />
		<parent link="elbowLeft" />
		<child link="wristYawLeft" />
		<axis xyz="0 0 1" />
		<limit effort="6.4" lower="-2.617" upper="2.617" velocity="4.9218" />
	</joint>
	<link name="wristPitchLeft">
		<inertial>
			<origin xyz="-0.00017580 0.00166098 -0.00002773" rpy="0 0 0" />
			<mass value="0.11963454" />
			<inertia ixx="0.00003359" ixy="0.00000002" ixz="0.00000000" iyy="0.00002690" iyz="-0.00000005" izz="0.00003977" />
		</inertial>
		<visual>
			<origin xyz="0 0 0" rpy="0 0 0" />
			<geometry>
				<mesh filename="../meshes/wristPitchLeft.dae" />
			</geometry>
			<material name="">
				<color rgba="1 1 1 1" />
			</material>
		</visual>
	</link>
	<joint name="wristPitch_Left" type="fixed">
		<origin xyz="0 0 -0.2017" rpy="0 0 0" />
		<parent link="wristYawLeft" />
		<child link="wristPitchLeft" />
		<axis xyz="0 1 0" />
		<limit effort="6.4" lower="-0.907" upper="0.907" velocity="4.9218" />
	</joint>
	<link name="wristRollLeft">
		<inertial>
			<origin xyz="-0.00235135 -0.00073844 -0.07225815" rpy="0 0 0" />
			<mass value="0.48947265" />
			<inertia ixx="0.00044320" ixy="0.00000818" ixz="-0.00000581" iyy="0.00063365" iyz="-0.00001568" izz="0.00028512" />
		</inertial>
		<visual>
			<origin xyz="0 0 0" rpy="0 0 0" />
			<geometry>
				<mesh filename="../meshes/inspire_Left.dae" />
			</geometry>
			<material name="">
				<color rgba="0.752941176470588 0.752941176470588 0.752941176470588 1" />
			</material>
		</visual>
		<collision>
			<origin xyz="0 0 0" rpy="0 0 0" />
			<geometry>
				<mesh filename="../meshes/inspire_Left.dae" />
			</geometry>
		</collision>
	</link>
	<joint name="wristRoll_Left" type="fixed">
		<origin xyz="0 0 0" rpy="0 0 0" />
		<parent link="wristPitchLeft" />
		<child link="wristRollLeft" />
		<axis xyz="1 0 0" />
		<limit effort="6.4" lower="-0.907" upper="0.907" velocity="4.9218" />
	</joint>
	<link name="L_thumb_proximal_base">
		<inertial>
			<origin xyz="-0.0048772 0.00668 -0.00044071" rpy="0 0 0" />
			<mass value="0.0018869" />
			<inertia ixx="5.2003E-08" ixy="4.8353E-09" ixz="6.6444E-09" iyy="6.7434E-08" iyz="-5.4476E-10" izz="8.5319E-08" />
		</inertial>
		<visual>
			<origin xyz="0 0 0" rpy="0 0.3 0" />
			<geometry>
				<mesh filename="../meshes/L_thumb_proximal_base.dae" />
			</geometry>
			<material name="">
				<color rgba="1 1 1 1" />
			</material>
		</visual>
		<collision>
			<origin xyz="0 0 0" rpy="0 0.3 0" />
			<geometry>
				<mesh filename="../meshes/L_thumb_proximal_base.dae" />
			</geometry>
		</collision>
	</link>
	<joint name="L_thumb_MCP_joint1" type="fixed">
		<origin xyz="0.020450106 -0.016955517 -0.045202411" rpy="-1.5708 0 2.9722026" />
		<parent link="wristRollLeft" />
		<child link="L_thumb_proximal_base" />
		<axis xyz="0 1 0" />
		<limit lower="0" upper="1.1" effort="1.0" velocity="1" />
	</joint>
	<link name="L_thumb_proximal">
		<inertial>
			<origin xyz="-3.8578E-05 0.025335 0.0016982" rpy="0 0 0" />
			<mass value="0.0066101" />
			<inertia ixx="2.787E-06" ixy="1.3042E-10" ixz="1.3413E-09" iyy="8.9435E-07" iyz="2.1426E-07" izz="2.4105E-06" />
		</inertial>
		<visual>
			<origin xyz="0 0 0" rpy="0 0 0" />
			<geometry>
				<mesh filename="../meshes/L_thumb_proximal.dae" />
			</geometry>
			<material name="">
				<color rgba="1 1 1 1" />
			</material>
		</visual>
		<collision>
			<origin xyz="0 0 0" rpy="0 0 0" />
			<geometry>
				<mesh filename="../meshes/L_thumb_proximal.dae" />
			</geometry>
		</collision>
	</link>
	<joint name="L_thumb_MCP_joint2" type="fixed">
		<origin xyz="-0.0115 0.005 0.0034" rpy="0.5948037 -1.2708 0" />
		<parent link="L_thumb_proximal_base" />
		<child link="L_thumb_proximal" />
		<axis xyz="-1 0 0" />
		<limit lower="0" upper="0.5" effort="1.0" velocity="1" />
	</joint>
	<link name="L_thumb_intermediate">
		<inertial>
			<origin xyz="-1.7401E-07 0.0072516 0.0064286" rpy="0 0 0" />
			<mass value="0.0037844" />
			<inertia ixx="4.6532E-07" ixy="-9.1152E-13" ixz="-3.8682E-12" iyy="2.6856E-07" iyz="6.4144E-08" izz="4.252E-07" />
		</inertial>
		<visual>
			<origin xyz="0 0 0" rpy="0 0 0" />
			<geometry>
				<mesh filename="../meshes/L_thumb_intermediate.dae" />
			</geometry>
			<material name="">
				<color rgba="1 1 1 1" />
			</material>
		</visual>
		<collision>
			<origin xyz="0 0 0" rpy="0 0 0" />
			<geometry>
				<mesh filename="../meshes/L_thumb_intermediate.dae" />
			</geometry>
		</collision>
	</link>
	<joint name="L_thumb_PIP_joint" type="fixed">
		<origin xyz="0 0.055863 -0.0039241" rpy="0.038299 0 0" />
		<parent link="L_thumb_proximal" />
		<child link="L_thumb_intermediate" />
		<axis xyz="-1 0 0" />
		<limit lower="0" upper="1" effort="1.0" velocity="1" />
	</joint>
	<link name="L_thumb_distal">
		<inertial>
			<origin xyz="-3.3076E-06 0.010511 0.00057861" rpy="0 0 0" />
			<mass value="0.003344" />
			<inertia ixx="2.0026E-07" ixy="-1.4157E-10" ixz="5.6213E-11" iyy="8.7108E-08" iyz="2.4414E-08" izz="1.8974E-07" />
		</inertial>
		<visual>
			<origin xyz="0 0 0" rpy="0 0 0" />
			<geometry>
				<mesh filename="../meshes/L_thumb_distal.dae" />
			</geometry>
			<material name="">
				<color rgba="1 1 1 1" />
			</material>
		</visual>
		<collision>
			<origin xyz="0 0 0" rpy="0 0 0" />
			<geometry>
				<mesh filename="../meshes/L_thumb_distal.dae" />
			</geometry>
		</collision>
	</link>
	<joint name="L_thumb_DIP_joint" type="fixed">
		<origin xyz="0 0.022558 0.0020717" rpy="0.011642 0 0" />
		<parent link="L_thumb_intermediate" />
		<child link="L_thumb_distal" />
		<axis xyz="-1 0 0" />
		<limit lower="0" upper="1.2" effort="1.0" velocity="1" />
	</joint>
	<link name="L_index_proximal">
		<inertial>
			<origin xyz="0.0080456 0.011884 -0.0016957" rpy="0 0 0" />
			<mass value="0.0042405" />
			<inertia ixx="6.9402E-07" ixy="1.4654E-11" ixz="-2.3231E-12" iyy="2.3041E-07" iyz="9.1802E-08" izz="6.4342E-07" />
		</inertial>
		<visual>
			<origin xyz="0 0 0" rpy="0 0 0" />
			<geometry>
				<mesh filename="../meshes/L_index_proximal.dae" />
			</geometry>
			<material name="">
				<color rgba="1 1 1 1" />
			</material>
		</visual>
		<collision>
			<origin xyz="0 0 0" rpy="0 0 0" />
			<geometry>
				<mesh filename="../meshes/L_index_proximal.dae" />
			</geometry>
		</collision>
	</link>
	<joint name="L_index_MCP_joint" type="fixed">
		<origin xyz="0.018231106 0.000284483 -0.127012411" rpy="-1.3208 -0.034907 0" />
		<parent link="wristRollLeft" />
		<child link="L_index_proximal" />
		<axis xyz="-1 0 0" />
		<limit lower="0" upper="1.7" effort="1.0" velocity="1" />
	</joint>
	<link name="L_index_distal">
		<inertial>
			<origin xyz="0.0063917 0.01959 -0.0019564" rpy="0 0 0" />
			<mass value="0.0045682" />
			<inertia ixx="7.8176E-07" ixy="-7.7162E-14" ixz="3.9272E-13" iyy="1.5634E-07" iyz="2.1006E-07" izz="7.0081E-07" />
		</inertial>
		<visual>
			<origin xyz="0 0 0" rpy="0 0 0" />
			<geometry>
				<mesh filename="../meshes/L_index_distal.dae" />
			</geometry>
			<material name="">
				<color rgba="1 1 1 1" />
			</material>
		</visual>
		<collision>
			<origin xyz="0 0 0" rpy="0 0 0" />
			<geometry>
				<mesh filename="../meshes/L_index_distal.dae" />
			</geometry>
		</collision>
	</link>
	<joint name="L_index_DIP_joint" type="fixed">
		<origin xyz="0.0016538 0.030445 -0.010275" rpy="-0.039748 0 0" />
		<parent link="L_index_proximal" />
		<child link="L_index_distal" />
		<axis xyz="-1 0 0" />
		<limit lower="0" upper="1.6" effort="1.0" velocity="1" />
	</joint>
	<link name="L_middle_proximal">
		<inertial>
			<origin xyz="0.0080653 0.011884 -0.0016957" rpy="0 0 0" />
			<mass value="0.0042405" />
			<inertia ixx="6.9402E-07" ixy="1.4338E-11" ixz="-2.3917E-12" iyy="2.3041E-07" iyz="9.1802E-08" izz="6.4342E-07" />
		</inertial>
		<visual>
			<origin xyz="0 0 0" rpy="0 0 0" />
			<geometry>
				<mesh filename="../meshes/L_middle_proximal.dae" />
			</geometry>
			<material name="">
				<color rgba="1 1 1 1" />
			</material>
		</visual>
		<collision>
			<origin xyz="0 0 0" rpy="0 0 0" />
			<geometry>
				<mesh filename="../meshes/L_middle_proximal.dae" />
			</geometry>
		</collision>
	</link>
	<joint name="L_middle_MCP_joint" type="fixed">
		<origin xyz="-0.001114894 0.000284483 -0.127012411" rpy="-1.3208 0 0" />
		<parent link="wristRollLeft" />
		<child link="L_middle_proximal" />
		<axis xyz="-1 0 0" />
		<limit lower="0" upper="1.7" effort="1.0" velocity="1" />
	</joint>
	<link name="L_middle_distal">
		<inertial>
			<origin xyz="0.0063955 0.020807 -0.0018039" rpy="0 0 0" />
			<mass value="0.0050397" />
			<inertia ixx="9.8385E-07" ixy="-4.0683E-12" ixz="-1.7233E-12" iyy="1.7328E-07" iyz="2.5594E-07" izz="8.9141E-07" />
		</inertial>
		<visual>
			<origin xyz="0 0 0" rpy="0 0 0" />
			<geometry>
				<mesh filename="../meshes/L_middle_distal.dae" />
			</geometry>
			<material name="">
				<color rgba="1 1 1 1" />
			</material>
		</visual>
		<collision>
			<origin xyz="0 0 0" rpy="0 0 0" />
			<geometry>
				<mesh filename="../meshes/L_middle_distal.dae" />
			</geometry>
		</collision>
	</link>
	<joint name="L_middle_DIP_joint" type="fixed">
		<origin xyz="0.0016698 0.030445 -0.010275" rpy="-0.071413 0 0" />
		<parent link="L_middle_proximal" />
		<child link="L_middle_distal" />
		<axis xyz="-1 0 0" />
		<limit lower="0" upper="1.6" effort="1.0" velocity="1" />
	</joint>
	<link name="L_ring_proximal">
		<inertial>
			<origin xyz="0.010821 0.011884 -0.0016957" rpy="0 0 0" />
			<mass value="0.0042405" />
			<inertia ixx="6.9402E-07" ixy="1.3923E-11" ixz="-2.5637E-12" iyy="2.3041E-07" iyz="9.1802E-08" izz="6.4342E-07" />
		</inertial>
		<visual>
			<origin xyz="0 0 0" rpy="0 0 0" />
			<geometry>
				<mesh filename="../meshes/L_ring_proximal.dae" />
			</geometry>
			<material name="">
				<color rgba="1 1 1 1" />
			</material>
		</visual>
		<collision>
			<origin xyz="0 0 0" rpy="0 0 0" />
			<geometry>
				<mesh filename="../meshes/L_ring_proximal.dae" />
			</geometry>
		</collision>
	</link>
	<joint name="L_ring_MCP_joint" type="fixed">
		<origin xyz="-0.023084894 0.000284483 -0.126032411" rpy="-1.3208 0.05236 0" />
		<parent link="wristRollLeft" />
		<child link="L_ring_proximal" />
		<axis xyz="-1 0 0" />
		<limit lower="0" upper="1.7" effort="1.0" velocity="1" />
	</joint>
	<link name="L_ring_distal">
		<inertial>
			<origin xyz="0.009285 0.019591 -0.0019565" rpy="0 0 0" />
			<mass value="0.0045682" />
			<inertia ixx="7.8176E-07" ixy="4.4486E-13" ixz="-6.071E-14" iyy="1.5634E-07" iyz="2.1006E-07" izz="7.0081E-07" />
		</inertial>
		<visual>
			<origin xyz="0 0 0" rpy="0 0 0" />
			<geometry>
				<mesh filename="../meshes/L_ring_distal.dae" />
			</geometry>
			<material name="">
				<color rgba="1 1 1 1" />
			</material>
		</visual>
		<collision>
			<origin xyz="0 0 0" rpy="0 0 0" />
			<geometry>
				<mesh filename="../meshes/L_ring_distal.dae" />
			</geometry>
		</collision>
	</link>
	<joint name="L_ring_DIP_joint" type="fixed">
		<origin xyz="0.0015355 0.030445 -0.010275" rpy="-0.039748 0 0" />
		<parent link="L_ring_proximal" />
		<child link="L_ring_distal" />
		<axis xyz="-1 0 0" />
		<limit lower="0" upper="1.6" effort="1.0" velocity="1" />
	</joint>
	<link name="L_pinky_proximal">
		<inertial>
			<origin xyz="0.013546 0.011884 -0.0016957" rpy="0 0 0" />
			<mass value="0.0042405" />
			<inertia ixx="6.9402E-07" ixy="1.4088E-11" ixz="-2.5363E-12" iyy="2.3041E-07" iyz="9.1802E-08" izz="6.4342E-07" />
		</inertial>
		<visual>
			<origin xyz="0 0 0" rpy="0 0 0" />
			<geometry>
				<mesh filename="../meshes/L_pinky_proximal.dae" />
			</geometry>
			<material name="">
				<color rgba="1 1 1 1" />
			</material>
		</visual>
		<collision>
			<origin xyz="0 0 0" rpy="0 0 0" />
			<geometry>
				<mesh filename="../meshes/L_pinky_proximal.dae" />
			</geometry>
		</collision>
	</link>
	<joint name="L_pinky_MCP_joint" type="fixed">
		<origin xyz="-0.044926894 0.000284483 -0.123672411" rpy="-1.3208 0.10472 0" />
		<parent link="wristRollLeft" />
		<child link="L_pinky_proximal" />
		<axis xyz="-1 0 0" />
		<limit lower="0" upper="1.7" effort="1.0" velocity="1" />
	</joint>
	<link name="L_pinky_distal">
		<inertial>
			<origin xyz="0.013546 0.016245 -0.0022219" rpy="0 0 0" />
			<mass value="0.0036036" />
			<inertia ixx="4.4881E-07" ixy="-2.6544E-12" ixz="2.0643E-12" iyy="1.2252E-07" iyz="1.3507E-07" izz="3.8703E-07" />
		</inertial>
		<visual>
			<origin xyz="0 0 0" rpy="0 0 0" />
			<geometry>
				<mesh filename="../meshes/L_pinky_distal.dae" />
			</geometry>
			<material name="">
				<color rgba="1 1 1 1" />
			</material>
		</visual>
		<collision>
			<origin xyz="0 0 0" rpy="0 0 0" />
			<geometry>
				<mesh filename="../meshes/L_pinky_distal.dae" />
			</geometry>
		</collision>
	</link>
	<joint name="L_pinky_DIP_joint" type="fixed">
		<origin xyz="0 0.030445 -0.010275" rpy="0.037691 0 0" />
		<parent link="L_pinky_proximal" />
		<child link="L_pinky_distal" />
		<axis xyz="-1 0 0" />
		<limit lower="0" upper="1.6" effort="1.0" velocity="1" />
	</joint>
	<link name="shoulderPitchRight">
		<inertial>
			<origin xyz="-0.00150404 -0.02687227 0.00010766" rpy="0 0 0" />
			<mass value="0.20310000" />
			<inertia ixx="0.00017009" ixy="0.00000447" ixz="-0.00000064" iyy="0.00028895" iyz="-0.00000043" izz="0.00034374" />
		</inertial>
		<visual>
			<origin xyz="0 0 0" rpy="0 0 0" />
			<geometry>
				<mesh filename="../meshes/shoulderPitchRight.dae" />
			</geometry>
			<material name="">
				<color rgba="1 1 1 1" />
			</material>
		</visual>
	</link>
	<joint name="shoulderPitch_Right" type="revolute">
		<origin xyz="0 -0.16011 0.25742" rpy="-0.34907 0 0" />
		<parent link="torso" />
		<child link="shoulderPitchRight" />
		<axis xyz="0 1 0" />
		<limit effort="65.0" lower="-3.560" upper="1.989" velocity="8.0" />
	</joint>
	<link name="shoulderRollRight">
		<inertial>
			<origin xyz="-0.02860454 -0.01104592 -0.01404986" rpy="0 0 0" />
			<mass value="0.72480000" />
			<inertia ixx="0.00090814" ixy="0.00002628" ixz="0.00003990" iyy="0.00071184" iyz="0.00025129" izz="0.00060969" />
		</inertial>
		<visual>
			<origin xyz="0 0 0" rpy="0 0 0" />
			<geometry>
				<mesh filename="../meshes/shoulderRollRight.dae" />
			</geometry>
			<material name="">
				<color rgba="1 1 1 1" />
			</material>
		</visual>
		<collision>
			<origin xyz="-0.035 0 0" rpy="0 1.5708 0" />
			<geometry>
				<cylinder length="0.02" radius="0.035" />
			</geometry>
		</collision>
	</link>
	<joint name="shoulderRoll_Right" type="revolute">
		<origin xyz="0.0335 -0.0435 0" rpy="0.34907 0 0" />
		<parent link="shoulderPitchRight" />
		<child link="shoulderRollRight" />
		<axis xyz="1 0 0" />
		<limit effort="65.0" lower="-2.74" upper="0.575" velocity="8.0" />
	</joint>
	<link name="shoulderYawRight">
		<inertial>
			<origin xyz="-0.00089274 -0.00096643 -0.06980518" rpy="0 0 0" />
			<mass value="0.69630000" />
			<inertia ixx="0.00304636" ixy="-0.00000070" ixz="0.00005211" iyy="0.00297764" iyz="0.00008904" izz="0.00041751" />
		</inertial>
		<visual>
			<origin xyz="0 0 0" rpy="0 0 0" />
			<geometry>
				<mesh filename="../meshes/shoulderYawRight.dae" />
			</geometry>
			<material name="">
				<color rgba="1 1 1 1" />
			</material>
		</visual>
		<collision>
			<origin xyz="0 0 -0.06" rpy="0 0 0" />
			<geometry>
				<cylinder length="0.067" radius="0.0415" />
			</geometry>
		</collision>
	</link>
	<joint name="shoulderYaw_Right" type="revolute">
		<origin xyz="-0.0335 -0.034 -0.0585" rpy="0 0 0" />
		<parent link="shoulderRollRight" />
		<child link="shoulderYawRight" />
		<axis xyz="0 0 1" />
		<limit effort="65.0" lower="-1.6" upper="1.6" velocity="8.0" />
	</joint>
	<link name="elbowRight">
		<inertial>
			<origin xyz="-0.01212328 -0.02629569 -0.02658404" rpy="0 0 0" />
			<mass value="0.85400000" />
			<inertia ixx="0.00099546" ixy="0.00002241" ixz="0.00027937" iyy="0.00111379" iyz="0.00004820" izz="0.00053993" />
		</inertial>
		<visual>
			<origin xyz="0 0 0" rpy="0 0 0" />
			<geometry>
				<mesh filename="../meshes/elbowRight.dae" />
			</geometry>
			<material name="">
				<color rgba="1 1 1 1" />
			</material>
		</visual>
	</link>
	<joint name="elbow_Right" type="revolute">
		<origin xyz="0 0.0285 -0.20415" rpy="0 0 0" />
		<parent link="shoulderYawRight" />
		<child link="elbowRight" />
		<axis xyz="0 1 0" />
		<limit effort="30.0" lower="-2.0" upper="0.0" velocity="8.0" />
	</joint>
	<link name="wristYawRight">
		<inertial>
			<origin xyz="-0.00202981 -0.00013146 -0.09216894" rpy="0 0 0" />
			<mass value="0.95587832" />
			<inertia ixx="0.00256092" ixy="0.00000273" ixz="0.00003067" iyy="0.00250028" iyz="0.00002722" izz="0.00055059" />
		</inertial>
		<visual>
			<origin xyz="0 0 0" rpy="0 0 0" />
			<geometry>
				<mesh filename="../meshes/wristYawRight.dae" />
			</geometry>
			<material name="">
				<color rgba="1 1 1 1" />
			</material>
		</visual>
		<collision>
			<origin xyz="0 0 -0.09" rpy="0 0 0" />
			<geometry>
				<cylinder length="0.1" radius="0.038"/>
			</geometry>
		</collision>
	</link>
	<joint name="wristYaw_Right" type="fixed">
		<origin xyz="-0.025 -0.0285 -0.0729" rpy="0 0 0" />
		<parent link="elbowRight" />
		<child link="wristYawRight" />
		<axis xyz="0 0 1" />
		<limit effort="6.4" lower="-2.617" upper="2.617" velocity="4.9218" />
	</joint>
	<link name="wristPitchRight">
		<inertial>
			<origin xyz="-0.00017580 0.00166098 -0.00002773" rpy="0 0 0" />
			<mass value="0.11963454" />
			<inertia ixx="0.00003359" ixy="0.00000002" ixz="0.00000000" iyy="0.00002690" iyz="-0.00000005" izz="0.00003977" />
		</inertial>
		<visual>
			<origin xyz="0 0 0" rpy="0 0 0" />
			<geometry>
				<mesh filename="../meshes/wristPitchRight.dae" />
			</geometry>
			<material name="">
				<color rgba="1 1 1 1" />
			</material>
		</visual>
	</link>
	<joint name="wristPitch_Right" type="fixed">
		<origin xyz="0 0 -0.201699999719004" rpy="0 0 0" />
		<parent link="wristYawRight" />
		<child link="wristPitchRight" />
		<axis xyz="0 1 0" />
		<limit effort="6.4" lower="-0.907" upper="0.907" velocity="4.9218" />
	</joint>
	<link name="wristRollRight">
		<inertial>
			<origin xyz="-0.00235219 0.00073858 -0.07225807" rpy="0 0 0" />
			<mass value="0.48947185" />
			<inertia ixx="0.00044319" ixy="-0.00000818" ixz="-0.00000581" iyy="0.00063364" iyz="0.00001568" izz="0.00028512" />
		</inertial>
		<visual>
			<origin xyz="0 0 0" rpy="0 0 0" />
			<geometry>
				<mesh filename="../meshes/inspire_Right.dae" />
			</geometry>
			<material name="">
				<color rgba="0.752941176470588 0.752941176470588 0.752941176470588 1" />
			</material>
		</visual>
		<collision>
			<origin xyz="0 0 0" rpy="0 0 0" />
			<geometry>
				<mesh filename="../meshes/inspire_Right.dae" />
			</geometry>
		</collision>
	</link>
	<joint name="wristRoll_Right" type="fixed">
		<origin xyz="0 0 0" rpy="0 0 0" />
		<parent link="wristPitchRight" />
		<child link="wristRollRight" />
		<axis xyz="1 0 0" />
		<limit effort="6.4" lower="-0.907" upper="0.907" velocity="4.9218" />
	</joint>
	<link name="R_thumb_proximal_base">
		<inertial>
			<origin xyz="-0.00382764881053596 -0.0107181618219411 0.000559765736006684" rpy="0 0 0" />
			<mass value="0.00151773698887962" />
			<inertia ixx="3.60087080879981E-08" ixy="-1.96095506259986E-09" ixz="-5.66955703371013E-09" iyy="5.6161096564387E-08" iyz="-1.99374406008934E-10" izz="6.0787820658132E-08" />
		</inertial>
		<visual>
			<origin xyz="0 0 0" rpy="0 0 0" />
			<geometry>
				<mesh filename="../meshes/R_thumb_proximal_base.dae" />
			</geometry>
			<material name="">
				<color rgba="0.752941176470588 0.752941176470588 0.752941176470588 1" />
			</material>
		</visual>
		<collision>
			<origin xyz="0 0 0" rpy="0 0 0" />
			<geometry>
				<mesh filename="../meshes/R_thumb_proximal_base.dae" />
			</geometry>
		</collision>
	</link>
	<joint name="R_thumb_MCP_joint1" type="fixed">
		<origin xyz="0.0204501060000028 0.0169555170000098 -0.061693589" rpy="-1.57078530718744 0 -2.67727777418532" />
		<parent link="wristRollRight" />
		<child link="R_thumb_proximal_base" />
		<axis xyz="0 -1 0" />
		<limit lower="0" upper="1.1" effort="1.0" velocity="1" />
	</joint>
	<link name="R_thumb_proximal">
		<inertial>
			<origin xyz="-0.000117809754724056 0.0258571423805095 -0.00100758942644689" rpy="0 0 0" />
			<mass value="0.0261115841107002" />
			<inertia ixx="7.93931587879801E-06" ixy="1.48009708452218E-08" ixz="-3.38204029822359E-09" iyy="2.41312609527012E-06" iyz="-1.30100404690884E-07" izz="6.72250735621506E-06" />
		</inertial>
		<visual>
			<origin xyz="0 0 0" rpy="0 0 0" />
			<geometry>
				<mesh filename="../meshes/R_thumb_proximal.dae" />
			</geometry>
			<material name="">
				<color rgba="0.752941176470588 0.752941176470588 0.752941176470588 1" />
			</material>
		</visual>
		<collision>
			<origin xyz="0 0 0" rpy="0 0 0" />
			<geometry>
				<mesh filename="../meshes/R_thumb_proximal.dae" />
			</geometry>
		</collision>
	</link>
	<joint name="R_thumb_MCP_joint2" type="fixed">
		<origin xyz="-0.0114999999999978 -0.011843 0" rpy="2.41138809480577 1.57079265360577 3.14159265198266" />
		<parent link="R_thumb_proximal_base" />
		<child link="R_thumb_proximal" />
		<axis xyz="1 0 0" />
		<limit lower="0" upper="0.5" effort="1.0" velocity="1" />
	</joint>
	<link name="R_thumb_intermediate">
		<inertial>
			<origin xyz="-0.000229619674236775 0.00972594453741249 -0.0056973693761041" rpy="0 0 0" />
			<mass value="0.00762416186974198" />
			<inertia ixx="8.63217330998741E-07" ixy="1.18238650825234E-09" ixz="4.34180082922964E-11" iyy="3.66252085743616E-07" iyz="-8.29334502637433E-08" izz="7.95816234979935E-07" />
		</inertial>
		<visual>
			<origin xyz="0 0 0" rpy="0 0 0" />
			<geometry>
				<mesh filename="../meshes/R_thumb_intermediate.dae" />
			</geometry>
			<material name="">
				<color rgba="0.752941176470588 0.752941176470588 0.752941176470588 1" />
			</material>
		</visual>
		<collision>
			<origin xyz="0 0 0" rpy="0 0 0" />
			<geometry>
				<mesh filename="../meshes/R_thumb_intermediate.dae" />
			</geometry>
		</collision>
	</link>
	<joint name="R_thumb_PIP_joint" type="fixed">
		<origin xyz="0 0.0558629999999866 0.00392410000000695" rpy="-0.0382990000074394 0 0" />
		<parent link="R_thumb_proximal" />
		<child link="R_thumb_intermediate" />
		<axis xyz="1 0 0" />
		<limit lower="0" upper="1" effort="1.0" velocity="1" />
	</joint>
	<link name="R_thumb_distal">
		<inertial>
			<origin xyz="-0.000295905109829989 0.0107670545015768 -0.00301220801911901" rpy="0 0 0" />
			<mass value="0.00320232682951003" />
			<inertia ixx="1.86499290413194E-07" ixy="3.07936668015311E-10" ixz="-1.45970263564255E-11" iyy="7.66299569611685E-08" iyz="-2.44638579134461E-09" izz="1.79862828526633E-07" />
		</inertial>
		<visual>
			<origin xyz="0 0 0" rpy="0 0 0" />
			<geometry>
				<mesh filename="../meshes/R_thumb_distal.dae" />
			</geometry>
			<material name="">
				<color rgba="0.752941176470588 0.752941176470588 0.752941176470588 1" />
			</material>
		</visual>
		<collision>
			<origin xyz="0 0 0" rpy="0 0 0" />
			<geometry>
				<mesh filename="../meshes/R_thumb_distal.dae" />
			</geometry>
		</collision>
	</link>
	<joint name="R_thumb_DIP_joint" type="fixed">
		<origin xyz="0 0.0225579999999965 -0.00207169999999632" rpy="-0.0116419999984538 0 0" />
		<parent link="R_thumb_intermediate" />
		<child link="R_thumb_distal" />
		<axis xyz="1 0 0" />
		<limit lower="0" upper="1.2" effort="1.0" velocity="1" />
	</joint>
	<link name="R_index_proximal">
		<inertial>
			<origin xyz="0.00990135500742561 0.0133304136652114 0.00117936285982397" rpy="0 0 0" />
			<mass value="0.00701852522150007" />
			<inertia ixx="8.95726613028746E-07" ixy="-1.148920094866E-11" ixz="-3.18020240179009E-12" iyy="2.82953699148337E-07" iyz="-7.1219419325933E-08" izz="8.2572074500356E-07" />
		</inertial>
		<visual>
			<origin xyz="0 0 0" rpy="0 0 0" />
			<geometry>
				<mesh filename="../meshes/R_index_proximal.dae" />
			</geometry>
			<material name="">
				<color rgba="0.752941176470588 0.752941176470588 0.752941176470588 1" />
			</material>
		</visual>
		<collision>
			<origin xyz="0 0 0" rpy="0 0 0" />
			<geometry>
				<mesh filename="../meshes/R_index_proximal.dae" />
			</geometry>
		</collision>
	</link>
	<joint name="R_index_MCP_joint" type="fixed">
		<origin xyz="0.016376105999999 -0.000284482999995478 -0.127082589000005" rpy="-1.81478530717884 -0.0349070000000007 0" />
		<parent link="wristRollRight" />
		<child link="R_index_proximal" />
		<axis xyz="1 0 0" />
		<limit lower="0" upper="1.7" effort="1.0" velocity="1" />
	</joint>
	<link name="R_index_distal">
		<inertial>
			<origin xyz="0.00832615978706599 0.0195854179080407 -0.00337709473418676" rpy="0 0 0" />
			<mass value="0.00444688526691259" />
			<inertia ixx="7.46210721263786E-07" ixy="2.73612209843274E-12" ixz="2.55720470783722E-12" iyy="1.05450954689884E-07" iyz="-1.30534943168026E-07" izz="7.09638477603336E-07" />
		</inertial>
		<visual>
			<origin xyz="0 0 0" rpy="0 0 0" />
			<geometry>
				<mesh filename="../meshes/R_index_distal.dae" />
			</geometry>
			<material name="">
				<color rgba="0.752941176470588 0.752941176470588 0.752941176470588 1" />
			</material>
		</visual>
		<collision>
			<origin xyz="0 0 0" rpy="0 0 0" />
			<geometry>
				<mesh filename="../meshes/R_index_distal.dae" />
			</geometry>
		</collision>
	</link>
	<joint name="R_index_DIP_joint" type="fixed">
		<origin xyz="0.00157500000000335 0.0304450000000037 0.0102749999999737" rpy="0.0442880000000218 0 0" />
		<parent link="R_index_proximal" />
		<child link="R_index_distal" />
		<axis xyz="1 0 0" />
		<limit lower="0" upper="1.6" effort="1.0" velocity="1" />
	</joint>
	<link name="R_index_distalR_middle_proximal">
		<inertial>
			<origin xyz="0.00806492053336038 0.0133239385273582 0.00125954670221406" rpy="0 0 0" />
			<mass value="0.0070185317558805" />
			<inertia ixx="8.95728553122376E-07" ixy="-1.15940626961654E-11" ixz="-3.42128943781823E-12" iyy="2.83828882925209E-07" iyz="-7.44723781455968E-08" izz="8.24847413087409E-07" />
		</inertial>
		<visual>
			<origin xyz="0 0 0" rpy="0 0 0" />
			<geometry>
				<mesh filename="../meshes/R_index_distalR_middle_proximal.dae" />
			</geometry>
			<material name="">
				<color rgba="0.752941176470588 0.752941176470588 0.752941176470588 1" />
			</material>
		</visual>
		<collision>
			<origin xyz="0 0 0" rpy="0 0 0" />
			<geometry>
				<mesh filename="../meshes/R_index_distalR_middle_proximal.dae" />
			</geometry>
		</collision>
	</link>
	<joint name="R_middle_MCP_joint" type="fixed">
		<origin xyz="-0.001114893999998 -0.000284483000066449 -0.127099588999977" rpy="-1.82078530717921 0 0" />
		<parent link="wristRollRight" />
		<child link="R_index_distalR_middle_proximal" />
		<axis xyz="1 0 0" />
		<limit lower="0" upper="1.7" effort="1.0" velocity="1" />
	</joint>
	<link name="R_middle_distal">
		<inertial>
			<origin xyz="0.00639764910329568 0.0207583299109729 -0.00344503193080434" rpy="0 0 0" />
			<mass value="0.00489152423458158" />
			<inertia ixx="9.68779716193073E-07" ixy="1.00103343518395E-11" ixz="2.13540088399477E-12" iyy="1.12860193633169E-07" iyz="-1.470662072756E-07" izz="9.31723000066164E-07" />
		</inertial>
		<visual>
			<origin xyz="0 0 0" rpy="0 0 0" />
			<geometry>
				<mesh filename="../meshes/R_middle_distal.dae" />
			</geometry>
			<material name="">
				<color rgba="0.752941176470588 0.752941176470588 0.752941176470588 1" />
			</material>
		</visual>
		<collision>
			<origin xyz="0 0 0" rpy="0 0 0" />
			<geometry>
				<mesh filename="../meshes/R_middle_distal.dae" />
			</geometry>
		</collision>
	</link>
	<joint name="R_middle_DIP_joint" type="fixed">
		<origin xyz="0.00166729999999888 0.0304450000000022 0.0102750000000512" rpy="0.0714130000000114 0 0" />
		<parent link="R_index_distalR_middle_proximal" />
		<child link="R_middle_distal" />
		<axis xyz="1 0 0" />
		<limit lower="0" upper="1.6" effort="1.0" velocity="1" />
	</joint>
	<link name="R_ring_proximal">
		<inertial>
			<origin xyz="0.00802083529366671 0.0132340178107531 0.00156645676513759" rpy="0 0 0" />
			<mass value="0.00658140314195911" />
			<inertia ixx="8.77699356489043E-07" ixy="-7.2724341496541E-12" ixz="-3.16350537979834E-12" iyy="2.70922365687212E-07" iyz="-7.67818147493719E-08" izz="8.15640213128758E-07" />
		</inertial>
		<visual>
			<origin xyz="0 0 0" rpy="0 0 0" />
			<geometry>
				<mesh filename="../meshes/R_ring_proximal.dae" />
			</geometry>
			<material name="">
				<color rgba="0.752941176470588 0.752941176470588 0.752941176470588 1" />
			</material>
		</visual>
		<collision>
			<origin xyz="0 0 0" rpy="0 0 0" />
			<geometry>
				<mesh filename="../meshes/R_ring_proximal.dae" />
			</geometry>
		</collision>
	</link>
	<joint name="R_ring_MCP_joint" type="fixed">
		<origin xyz="-0.020288893999997 -0.000284483000030838 -0.126176588999991" rpy="-1.82078530717921 0.0523599999999982 0" />
		<parent link="wristRollRight" />
		<child link="R_ring_proximal" />
		<axis xyz="1 0 0" />
		<limit lower="0" upper="1.7" effort="1.0" velocity="1" />
	</joint>
	<link name="R_ring_distal">
		<inertial>
			<origin xyz="0.00802088818080873 0.0195658921497007 -0.00298540872724894" rpy="0 0 0" />
			<mass value="0.00444671038889567" />
			<inertia ixx="7.46188128027768E-07" ixy="9.86567206698211E-12" ixz="3.65302430361656E-12" iyy="1.08263786700982E-07" iyz="-1.368703521112E-07" izz="7.06800623149926E-07" />
		</inertial>
		<visual>
			<origin xyz="0 0 0" rpy="0 0 0" />
			<geometry>
				<mesh filename="../meshes/R_ring_distal.dae" />
			</geometry>
			<material name="">
				<color rgba="0.752941176470588 0.752941176470588 0.752941176470588 1" />
			</material>
		</visual>
		<collision>
			<origin xyz="0 0 0" rpy="0 0 0" />
			<geometry>
				<mesh filename="../meshes/R_ring_distal.dae" />
			</geometry>
		</collision>
	</link>
	<joint name="R_ring_DIP_joint" type="fixed">
		<origin xyz="0 0.0304449999999941 0.0102750000000099" rpy="0.0397480000000075 0 0" />
		<parent link="R_ring_proximal" />
		<child link="R_ring_distal" />
		<axis xyz="1 0 0" />
		<limit lower="0" upper="1.6" effort="1.0" velocity="1" />
	</joint>
	<link name="R_pinky_proximal">
		<inertial>
			<origin xyz="0.00788897714502957 0.0133869227067238 0.00101141410835032" rpy="0 0 0" />
			<mass value="0.00701853182876559" />
			<inertia ixx="8.95729441425343E-07" ixy="-1.18146961917887E-11" ixz="-3.54915778627984E-12" iyy="2.8382915120387E-07" iyz="-7.44730775821664E-08" izz="8.24848125349754E-07" />
		</inertial>
		<visual>
			<origin xyz="0 0 0" rpy="0 0 0" />
			<geometry>
				<mesh filename="../meshes/R_pinky_proximal.dae" />
			</geometry>
			<material name="">
				<color rgba="0.752941176470588 0.752941176470588 0.752941176470588 1" />
			</material>
		</visual>
		<collision>
			<origin xyz="0 0 0" rpy="0 0 0" />
			<geometry>
				<mesh filename="../meshes/R_pinky_proximal.dae" />
			</geometry>
		</collision>
	</link>
	<joint name="R_pinky_MCP_joint" type="fixed">
		<origin xyz="-0.039300893999997 -2.84830000677194E-05 -0.124262588999974" rpy="-1.82078530717921 0.10472 0" />
		<parent link="wristRollRight" />
		<child link="R_pinky_proximal" />
		<axis xyz="1 0 0" />
		<limit lower="0" upper="1.7" effort="1.0" velocity="1" />
	</joint>
	<link name="R_pinky_distal">
		<inertial>
			<origin xyz="0.00791918669793035 0.0166368770905698 -0.00279124266185325" rpy="0 0 0" />
			<mass value="0.00357986960061578" />
			<inertia ixx="4.28296885217303E-07" ixy="-6.19911495396114E-10" ixz="-3.02772463164244E-10" iyy="8.81645541081828E-08" iyz="-9.44288810237396E-08" izz="3.95700008437022E-07" />
		</inertial>
		<visual>
			<origin xyz="0 0 0" rpy="0 0 0" />
			<geometry>
				<mesh filename="../meshes/R_pinky_distal.dae" />
			</geometry>
			<material name="">
				<color rgba="0.752941176470588 0.752941176470588 0.752941176470588 1" />
			</material>
		</visual>
		<collision>
			<origin xyz="0 0 0" rpy="0 0 0" />
			<geometry>
				<mesh filename="../meshes/R_pinky_distal.dae" />
			</geometry>
		</collision>
	</link>
	<joint name="R_pinky_DIP_joint" type="fixed">
		<origin xyz="0 0.0304450000000081 0.0102750000001108" rpy="-0.0376910000000213 0 0" />
		<parent link="R_pinky_proximal" />
		<child link="R_pinky_distal" />
		<axis xyz="1 0 0" />
		<limit lower="0" upper="1.6" effort="1.0" velocity="1" />
	</joint>
</robot>
